Workbook

Sheet Accesos x Municipio
V1: D E N S I D A D / P E N E T R A C I O N D E I N T E R N E T
D2: A C C E S O S D E I N T E R N E T | N2: P O B L A C I O N | R2: H O G A R E S | V2: S O B R E P O B L A C I O N | Z2: S O B R E H O G A R E S
D3: =+[1]Total!$B$4 -> 2021 | H3: =+[1]Total!$G$4 -> 2022 | L3: 2023 | N3: 2020 | O3: =+N3+1 -> 2021 | P3: =+O3+1 -> 2022 | Q3: =+P3+1 -> 2023 | R3: 2020 | S3: =+R3+1 -> 2021 | T3: =+S3+1 -> 2022 | U3: =+T3+1 -> 2023 | V3: 2020 | W3: =+V3+1 -> 2021 | X3: =+W3+1 -> 2022 | Y3: =+X3+1 -> 2023 | Z3: 2020 | AA3: =+Z3+1 -> 2021 | AB3: =+AA3+1 -> 2022 | AC3: =+AB3+1 -> 2023 | AD3: Hogares con penetración <=20%
C4: Municipio | D4: =+[1]Total!B5 -> 1 | E4: =+[1]Total!C5 -> 2 | F4: =+[1]Total!D5 -> 3 | G4: =+[1]Total!E5 -> 4 | H4: =+[1]Total!G5 -> 1 | I4: =+[1]Total!H5 -> 2 | J4: =+[1]Total!I5 -> 3 | K4: =+[1]Total!J5 -> 4 | L4: =+[1]Total!L5 -> 1 | M4: =+[1]Total!M5 -> 2 | AA4: =+AA3 -> 2021 | AB4: =+AB3 -> 2022 | AC4: =+AC3 -> 2023 | AD4: Hogares | AE4: Accesos | AF4: No cubiertos
B5: 05001 | C5: =VLOOKUP(B5,[2]Municipal!$C$15:$D$60549,2) -> Medellín | D5: =+[1]Total!B6 -> 683151 | E5: =+[1]Total!C6 -> 684313 | F5: =+[1]Total!D6 -> 693014 | G5: =+[1]Total!E6 -> 702797 | H5: =+[1]Total!G6 -> 729079 | I5: =+[1]Total!H6 -> 743054 | J5: =+[1]Total!I6 -> 748439 | K5: =+[1]Total!J6 -> 769787 | L5: =+[1]Total!L6 -> 767702 | M5: =+[1]Total!M6 -> 772962 | N5: =VLOOKUP($B5,'[2]pop-2020-2023'!$I$5:$M$1126,2) -> 2519592 | O5: =VLOOKUP($B5,'[2]pop-2020-2023'!$I$5:$M$1126,3) -> 2549008 | P5: =VLOOKUP($B5,'[2]pop-2020-2023'!$I$5:$M$1126,4) -> 2572350 | Q5: =VLOOKUP($B5,'[2]pop-2020-2023'!$I$5:$M$1126,5) -> 2595300 | R5: =VLOOKUP($B5,'[3]Hogares total'!$D$5:$L$1126,6) -> 878480 | S5: =VLOOKUP($B5,'[3]Hogares total'!$D$5:$L$1126,7) -> 908775 | T5: =VLOOKUP($B5,'[3]Hogares total'!$D$5:$L$1126,8) -> 939966 | U5: =VLOOKUP($B5,'[3]Hogares total'!$D$5:$L$1126,9) -> 972037 | W5: =+$E5/O5 -> 0.26846248 | X5: =+$I5/P5 -> 0.28886194 | Y5: =+$M5/Q5 -> 0.29783146 | AA5: =+$E5/S5 -> 0.75300597 | AB5: =+$I5/T5 -> 0.79051157 | AC5: =+$M5/U5 -> 0.79519813 | AD5: =IF(AC5<=0.2,U5,"") | AE5: =IF(AC5<=0.2,M5,"") | AF5: =IF(AC5<=0.2,AD5-AE5,"") | AG5: =IF(AC5>100%,C5,"")
B6: 05002 | C6: =VLOOKUP(B6,[2]Municipal!$C$15:$D$60549,2) -> Abejorral | D6: =+[1]Total!B7 -> 2145 | E6: =+[1]Total!C7 -> 2345 | F6: =+[1]Total!D7 -> 2299 | G6: =+[1]Total!E7 -> 2230 | H6: =+[1]Total!G7 -> 2405 | I6: =+[1]Total!H7 -> 2424 | J6: =+[1]Total!I7 -> 2379 | K6: =+[1]Total!J7 -> 2318 | L6: =+[1]Total!L7 -> 1060 | M6: =+[1]Total!M7 -> 974 | N6: =VLOOKUP($B6,'[2]pop-2020-2023'!$I$5:$M$1126,2) -> 20823 | O6: =VLOOKUP($B6,'[2]pop-2020-2023'!$I$5:$M$1126,3) -> 20924 | P6: =VLOOKUP($B6,'[2]pop-2020-2023'!$I$5:$M$1126,4) -> 21109 | Q6: =VLOOKUP($B6,'[2]pop-2020-2023'!$I$5:$M$1126,5) -> 21297 | R6: =VLOOKUP($B6,'[3]Hogares total'!$D$5:$L$1126,6) -> 6942 | S6: =VLOOKUP($B6,'[3]Hogares total'!$D$5:$L$1126,7) -> 7177 | T6: =VLOOKUP($B6,'[3]Hogares total'!$D$5:$L$1126,8) -> 7411 | U6: =VLOOKUP($B6,'[3]Hogares total'!$D$5:$L$1126,9) -> 7650 | W6: =+$E6/O6 -> 0.11207226 | X6: =+$I6/P6 -> 0.11483254 | Y6: =+$M6/Q6 -> 0.045734141 | AA6: =+$E6/S6 -> 0.32673819 | AB6: =+$I6/T6 -> 0.32708137 | AC6: =+$M6/U6 -> 0.12732026 | AD6: =IF(AC6<=0.2,U6,"") -> 7650 | AE6: =IF(AC6<=0.2,M6,"") -> 974 | AF6: =IF(AC6<=0.2,AD6-AE6,"") -> 6676 | AG6: =IF(AC6>100%,C6,"")
B7: 05004 | C7: =VLOOKUP(B7,[2]Municipal!$C$15:$D$60549,2) -> Abriaquí | D7: =+[1]Total!B8 -> 147 | E7: =+[1]Total!C8 -> 153 | F7: =+[1]Total!D8 -> 156 | G7: =+[1]Total!E8 -> 155 | H7: =+[1]Total!G8 -> 160 | I7: =+[1]Total!H8 -> 160 | J7: =+[1]Total!I8 -> 148 | K7: =+[1]Total!J8 -> 149 | L7: =+[1]Total!L8 -> 144 | M7: =+[1]Total!M8 -> 140 | N7: =VLOOKUP($B7,'[2]pop-2020-2023'!$I$5:$M$1126,2) -> 2775 | O7: =VLOOKUP($B7,'[2]pop-2020-2023'!$I$5:$M$1126,3) -> 2777 | P7: =VLOOKUP($B7,'[2]pop-2020-2023'!$I$5:$M$1126,4) -> 2804 | Q7: =VLOOKUP($B7,'[2]pop-2020-2023'!$I$5:$M$1126,5) -> 2841 | R7: =VLOOKUP($B7,'[3]Hogares total'!$D$5:$L$1126,6) -> 968 | S7: =VLOOKUP($B7,'[3]Hogares total'!$D$5:$L$1126,7) -> 1004 | T7: =VLOOKUP($B7,'[3]Hogares total'!$D$5:$L$1126,8) -> 1036 | U7: =VLOOKUP($B7,'[3]Hogares total'!$D$5:$L$1126,9) -> 1071 | W7: =+$E7/O7 -> 0.055095427 | X7: =+$I7/P7 -> 0.057061341 | Y7: =+$M7/Q7 -> 0.049278423 | AA7: =+$E7/S7 -> 0.15239044 | AB7: =+$I7/T7 -> 0.15444015 | AC7: =+$M7/U7 -> 0.13071895 | AD7: =IF(AC7<=0.2,U7,"") -> 1071 | AE7: =IF(AC7<=0.2,M7,"") -> 140 | AF7: =IF(AC7<=0.2,AD7-AE7,"") -> 931 | AG7: =IF(AC7>100%,C7,"")
B8: 05021 | C8: =VLOOKUP(B8,[2]Municipal!$C$15:$D$60549,2) -> Alejandría | D8: =+[1]Total!B9 -> 190 | E8: =+[1]Total!C9 -> 402 | F8: =+[1]Total!D9 -> 442 | G8: =+[1]Total!E9 -> 335 | H8: =+[1]Total!G9 -> 668 | I8: =+[1]Total!H9 -> 442 | J8: =+[1]Total!I9 -> 545 | K8: =+[1]Total!J9 -> 632 | L8: =+[1]Total!L9 -> 588 | M8: =+[1]Total!M9 -> 102 | N8: =VLOOKUP($B8,'[2]pop-2020-2023'!$I$5:$M$1126,2) -> 4790 | O8: =VLOOKUP($B8,'[2]pop-2020-2023'!$I$5:$M$1126,3) -> 4845 | P8: =VLOOKUP($B8,'[2]pop-2020-2023'!$I$5:$M$1126,4) -> 4874 | Q8: =VLOOKUP($B8,'[2]pop-2020-2023'!$I$5:$M$1126,5) -> 4912 | R8: =VLOOKUP($B8,'[3]Hogares total'!$D$5:$L$1126,6) -> 1694 | S8: =VLOOKUP($B8,'[3]Hogares total'!$D$5:$L$1126,7) -> 1750 | T8: =VLOOKUP($B8,'[3]Hogares total'!$D$5:$L$1126,8) -> 1807 | U8: =VLOOKUP($B8,'[3]Hogares total'!$D$5:$L$1126,9) -> 1864 | W8: =+$E8/O8 -> 0.082972136 | X8: =+$I8/P8 -> 0.090685269 | Y8: =+$M8/Q8 -> 0.020765472 | AA8: =+$E8/S8 -> 0.22971429 | AB8: =+$I8/T8 -> 0.24460432 | AC8: =+$M8/U8 -> 0.05472103 | AD8: =IF(AC8<=0.2,U8,"") -> 1864 | AE8: =IF(AC8<=0.2,M8,"") -> 102 | AF8: =IF(AC8<=0.2,AD8-AE8,"") -> 1762 | AG8: =IF(AC8>100%,C8,"")
B9: 05030 | C9: =VLOOKUP(B9,[2]Municipal!$C$15:$D$60549,2) -> Amagá | D9: =+[1]Total!B10 -> 3416 | E9: =+[1]Total!C10 -> 3826 | F9: =+[1]Total!D10 -> 3770 | G9: =+[1]Total!E10 -> 3760 | H9: =+[1]Total!G10 -> 3670 | I9: =+[1]Total!H10 -> 3603 | J9: =+[1]Total!I10 -> 3625 | K9: =+[1]Total!J10 -> 3397 | L9: =+[1]Total!L10 -> 3608 | M9: =+[1]Total!M10 -> 3197 | N9: =VLOOKUP($B9,'[2]pop-2020-2023'!$I$5:$M$1126,2) -> 31262 | O9: =VLOOKUP($B9,'[2]pop-2020-2023'!$I$5:$M$1126,3) -> 31548 | P9: =VLOOKUP($B9,'[2]pop-2020-2023'!$I$5:$M$1126,4) -> 31851 | Q9: =VLOOKUP($B9,'[2]pop-2020-2023'!$I$5:$M$1126,5) -> 32142 | R9: =VLOOKUP($B9,'[3]Hogares total'!$D$5:$L$1126,6) -> 10371 | S9: =VLOOKUP($B9,'[3]Hogares total'!$D$5:$L$1126,7) -> 10699 | T9: =VLOOKUP($B9,'[3]Hogares total'!$D$5:$L$1126,8) -> 11033 | U9: =VLOOKUP($B9,'[3]Hogares total'!$D$5:$L$1126,9) -> 11379 | W9: =+$E9/O9 -> 0.12127552 | X9: =+$I9/P9 -> 0.11312047 | Y9: =+$M9/Q9 -> 0.099464875 | AA9: =+$E9/S9 -> 0.35760351 | AB9: =+$I9/T9 -> 0.32656576 | AC9: =+$M9/U9 -> 0.28095615 | AD9: =IF(AC9<=0.2,U9,"") | AE9: =IF(AC9<=0.2,M9,"") | AF9: =IF(AC9<=0.2,AD9-AE9,"") | AG9: =IF(AC9>100%,C9,"")
B10: 05031 | C10: =VLOOKUP(B10,[2]Municipal!$C$15:$D$60549,2) -> Amalfi | D10: =+[1]Total!B11 -> 1494 | E10: =+[1]Total!C11 -> 1810 | F10: =+[1]Total!D11 -> 1542 | G10: =+[1]Total!E11 -> 1472 | H10: =+[1]Total!G11 -> 1548 | I10: =+[1]Total!H11 -> 1409 | J10: =+[1]Total!I11 -> 1414 | K10: =+[1]Total!J11 -> 1372 | L10: =+[1]Total!L11 -> 1466 | M10: =+[1]Total!M11 -> 1024 | N10: =VLOOKUP($B10,'[2]pop-2020-2023'!$I$5:$M$1126,2) -> 26876 | O10: =VLOOKUP($B10,'[2]pop-2020-2023'!$I$5:$M$1126,3) -> 27155 | P10: =VLOOKUP($B10,'[2]pop-2020-2023'!$I$5:$M$1126,4) -> 27398 | Q10: =VLOOKUP($B10,'[2]pop-2020-2023'!$I$5:$M$1126,5) -> 27637 | R10: =VLOOKUP($B10,'[3]Hogares total'!$D$5:$L$1126,6) -> 9115 | S10: =VLOOKUP($B10,'[3]Hogares total'!$D$5:$L$1126,7) -> 9413 | T10: =VLOOKUP($B10,'[3]Hogares total'!$D$5:$L$1126,8) -> 9715 | U10: =VLOOKUP($B10,'[3]Hogares total'!$D$5:$L$1126,9) -> 10026 | W10: =+$E10/O10 -> 0.066654391 | X10: =+$I10/P10 -> 0.051427111 | Y10: =+$M10/Q10 -> 0.037051778 | AA10: =+$E10/S10 -> 0.19228726 | AB10: =+$I10/T10 -> 0.14503345 | AC10: =+$M10/U10 -> 0.10213445 | AD10: =IF(AC10<=0.2,U10,"") -> 10026 | AE10: =IF(AC10<=0.2,M10,"") -> 1024 | AF10: =IF(AC10<=0.2,AD10-AE10,"") -> 9002 | AG10: =IF(AC10>100%,C10,"")
B11: 05034 | C11: =VLOOKUP(B11,[2]Municipal!$C$15:$D$60549,2) -> Andes | D11: =+[1]Total!B12 -> 3416 | E11: =+[1]Total!C12 -> 3953 | F11: =+[1]Total!D12 -> 4016 | G11: =+[1]Total!E12 -> 4094 | H11: =+[1]Total!G12 -> 4166 | I11: =+[1]Total!H12 -> 4155 | J11: =+[1]Total!I12 -> 4289 | K11: =+[1]Total!J12 -> 4266 | L11: =+[1]Total!L12 -> 4221 | M11: =+[1]Total!M12 -> 3627 | N11: =VLOOKUP($B11,'[2]pop-2020-2023'!$I$5:$M$1126,2) -> 44614 | O11: =VLOOKUP($B11,'[2]pop-2020-2023'!$I$5:$M$1126,3) -> 44983 | P11: =VLOOKUP($B11,'[2]pop-2020-2023'!$I$5:$M$1126,4) -> 45394 | Q11: =VLOOKUP($B11,'[2]pop-2020-2023'!$I$5:$M$1126,5) -> 45796 | R11: =VLOOKUP($B11,'[3]Hogares total'!$D$5:$L$1126,6) -> 14180 | S11: =VLOOKUP($B11,'[3]Hogares total'!$D$5:$L$1126,7) -> 14635 | T11: =VLOOKUP($B11,'[3]Hogares total'!$D$5:$L$1126,8) -> 15095 | U11: =VLOOKUP($B11,'[3]Hogares total'!$D$5:$L$1126,9) -> 15573 | W11: =+$E11/O11 -> 0.087877643 | X11: =+$I11/P11 -> 0.091531921 | Y11: =+$M11/Q11 -> 0.079199057 | AA11: =+$E11/S11 -> 0.27010591 | AB11: =+$I11/T11 -> 0.27525671 | AC11: =+$M11/U11 -> 0.2329031 | AD11: =IF(AC11<=0.2,U11,"") | AE11: =IF(AC11<=0.2,M11,"") | AF11: =IF(AC11<=0.2,AD11-AE11,"") | AG11: =IF(AC11>100%,C11,"")
B12: 05036 | C12: =VLOOKUP(B12,[2]Municipal!$C$15:$D$60549,2) -> Angelópolis | D12: =+[1]Total!B13 -> 299 | E12: =+[1]Total!C13 -> 444 | F12: =+[1]Total!D13 -> 429 | G12: =+[1]Total!E13 -> 429 | H12: =+[1]Total!G13 -> 520 | I12: =+[1]Total!H13 -> 575 | J12: =+[1]Total!I13 -> 660 | K12: =+[1]Total!J13 -> 566 | L12: =+[1]Total!L13 -> 578 | M12: =+[1]Total!M13 -> 396 | N12: =VLOOKUP($B12,'[2]pop-2020-2023'!$I$5:$M$1126,2) -> 5905 | O12: =VLOOKUP($B12,'[2]pop-2020-2023'!$I$5:$M$1126,3) -> 5963 | P12: =VLOOKUP($B12,'[2]pop-2020-2023'!$I$5:$M$1126,4) -> 6010 | Q12: =VLOOKUP($B12,'[2]pop-2020-2023'!$I$5:$M$1126,5) -> 6082 | R12: =VLOOKUP($B12,'[3]Hogares total'!$D$5:$L$1126,6) -> 2003 | S12: =VLOOKUP($B12,'[3]Hogares total'!$D$5:$L$1126,7) -> 2069 | T12: =VLOOKUP($B12,'[3]Hogares total'!$D$5:$L$1126,8) -> 2136 | U12: =VLOOKUP($B12,'[3]Hogares total'!$D$5:$L$1126,9) -> 2203 | W12: =+$E12/O12 -> 0.074459165 | X12: =+$I12/P12 -> 0.095673877 | Y12: =+$M12/Q12 -> 0.065110161 | AA12: =+$E12/S12 -> 0.21459642 | AB12: =+$I12/T12 -> 0.26919476 | AC12: =+$M12/U12 -> 0.17975488 | AD12: =IF(AC12<=0.2,U12,"") -> 2203 | AE12: =IF(AC12<=0.2,M12,"") -> 396 | AF12: =IF(AC12<=0.2,AD12-AE12,"") -> 1807 | AG12: =IF(AC12>100%,C12,"")
B13: 05038 | C13: =VLOOKUP(B13,[2]Municipal!$C$15:$D$60549,2) -> Angostura | D13: =+[1]Total!B14 -> 507 | E13: =+[1]Total!C14 -> 518 | F13: =+[1]Total!D14 -> 528 | G13: =+[1]Total!E14 -> 527 | H13: =+[1]Total!G14 -> 521 | I13: =+[1]Total!H14 -> 541 | J13: =+[1]Total!I14 -> 461 | K13: =+[1]Total!J14 -> 436 | L13: =+[1]Total!L14 -> 410 | M13: =+[1]Total!M14 -> 372 | N13: =VLOOKUP($B13,'[2]pop-2020-2023'!$I$5:$M$1126,2) -> 11742 | O13: =VLOOKUP($B13,'[2]pop-2020-2023'!$I$5:$M$1126,3) -> 11783 | P13: =VLOOKUP($B13,'[2]pop-2020-2023'!$I$5:$M$1126,4) -> 11909 | Q13: =VLOOKUP($B13,'[2]pop-2020-2023'!$I$5:$M$1126,5) -> 12005 | R13: =VLOOKUP($B13,'[3]Hogares total'!$D$5:$L$1126,6) -> 3635 | S13: =VLOOKUP($B13,'[3]Hogares total'!$D$5:$L$1126,7) -> 3762 | T13: =VLOOKUP($B13,'[3]Hogares total'!$D$5:$L$1126,8) -> 3886 | U13: =VLOOKUP($B13,'[3]Hogares total'!$D$5:$L$1126,9) -> 4012 | W13: =+$E13/O13 -> 0.04396164 | X13: =+$I13/P13 -> 0.045427828 | Y13: =+$M13/Q13 -> 0.030987089 | AA13: =+$E13/S13 -> 0.13769272 | AB13: =+$I13/T13 -> 0.1392177 | AC13: =+$M13/U13 -> 0.092721834 | AD13: =IF(AC13<=0.2,U13,"") -> 4012 | AE13: =IF(AC13<=0.2,M13,"") -> 372 | AF13: =IF(AC13<=0.2,AD13-AE13,"") -> 3640 | AG13: =IF(AC13>100%,C13,"")
B14: 05040 | C14: =VLOOKUP(B14,[2]Municipal!$C$15:$D$60549,2) -> Anorí | D14: =+[1]Total!B15 -> 1278 | E14: =+[1]Total!C15 -> 1262 | F14: =+[1]Total!D15 -> 1307 | G14: =+[1]Total!E15 -> 1286 | H14: =+[1]Total!G15 -> 1268 | I14: =+[1]Total!H15 -> 1823 | J14: =+[1]Total!I15 -> 1919 | K14: =+[1]Total!J15 -> 1863 | L14: =+[1]Total!L15 -> 1794 | M14: =+[1]Total!M15 -> 1823 | N14: =VLOOKUP($B14,'[2]pop-2020-2023'!$I$5:$M$1126,2) -> 18978 | O14: =VLOOKUP($B14,'[2]pop-2020-2023'!$I$5:$M$1126,3) -> 19192 | P14: =VLOOKUP($B14,'[2]pop-2020-2023'!$I$5:$M$1126,4) -> 19349 | Q14: =VLOOKUP($B14,'[2]pop-2020-2023'!$I$5:$M$1126,5) -> 19527 | R14: =VLOOKUP($B14,'[3]Hogares total'!$D$5:$L$1126,6) -> 6257 | S14: =VLOOKUP($B14,'[3]Hogares total'!$D$5:$L$1126,7) -> 6457 | T14: =VLOOKUP($B14,'[3]Hogares total'!$D$5:$L$1126,8) -> 6658 | U14: =VLOOKUP($B14,'[3]Hogares total'!$D$5:$L$1126,9) -> 6865 | W14: =+$E14/O14 -> 0.065756565 | X14: =+$I14/P14 -> 0.094216755 | Y14: =+$M14/Q14 -> 0.093357915 | AA14: =+$E14/S14 -> 0.1954468 | AB14: =+$I14/T14 -> 0.27380595 | AC14: =+$M14/U14 -> 0.26554989 | AD14: =IF(AC14<=0.2,U14,"") | AE14: =IF(AC14<=0.2,M14,"") | AF14: =IF(AC14<=0.2,AD14-AE14,"") | AG14: =IF(AC14>100%,C14,"")
B15: 05042 | C15: =VLOOKUP(B15,[2]Municipal!$C$15:$D$60549,2) -> Santafé de Antioquia | D15: =+[1]Total!B16 -> 3036 | E15: =+[1]Total!C16 -> 3502 | F15: =+[1]Total!D16 -> 4311 | G15: =+[1]Total!E16 -> 4374 | H15: =+[1]Total!G16 -> 3632 | I15: =+[1]Total!H16 -> 4472 | J15: =+[1]Total!I16 -> 3811 | K15: =+[1]Total!J16 -> 3944 | L15: =+[1]Total!L16 -> 3843 | M15: =+[1]Total!M16 -> 3396 | N15: =VLOOKUP($B15,'[2]pop-2020-2023'!$I$5:$M$1126,2) -> 27071 | O15: =VLOOKUP($B15,'[2]pop-2020-2023'!$I$5:$M$1126,3) -> 27327 | P15: =VLOOKUP($B15,'[2]pop-2020-2023'!$I$5:$M$1126,4) -> 27596 | Q15: =VLOOKUP($B15,'[2]pop-2020-2023'!$I$5:$M$1126,5) -> 27831 | R15: =VLOOKUP($B15,'[3]Hogares total'!$D$5:$L$1126,6) -> 9431 | S15: =VLOOKUP($B15,'[3]Hogares total'!$D$5:$L$1126,7) -> 9760 | T15: =VLOOKUP($B15,'[3]Hogares total'!$D$5:$L$1126,8) -> 10086 | U15: =VLOOKUP($B15,'[3]Hogares total'!$D$5:$L$1126,9) -> 10422 | W15: =+$E15/O15 -> 0.12815164 | X15: =+$I15/P15 -> 0.16205247 | Y15: =+$M15/Q15 -> 0.12202221 | AA15: =+$E15/S15 -> 0.35881148 | AB15: =+$I15/T15 -> 0.44338687 | AC15: =+$M15/U15 -> 0.32584917 | AD15: =IF(AC15<=0.2,U15,"") | AE15: =IF(AC15<=0.2,M15,"") | AF15: =IF(AC15<=0.2,AD15-AE15,"") | AG15: =IF(AC15>100%,C15,"")
B16: 05044 | C16: =VLOOKUP(B16,[2]Municipal!$C$15:$D$60549,2) -> Anzá | D16: =+[1]Total!B17 -> 237 | E16: =+[1]Total!C17 -> 867 | F16: =+[1]Total!D17 -> 905 | G16: =+[1]Total!E17 -> 862 | H16: =+[1]Total!G17 -> 864 | I16: =+[1]Total!H17 -> 863 | J16: =+[1]Total!I17 -> 1137 | K16: =+[1]Total!J17 -> 1049 | L16: =+[1]Total!L17 -> 704 | M16: =+[1]Total!M17 -> 842 | N16: =VLOOKUP($B16,'[2]pop-2020-2023'!$I$5:$M$1126,2) -> 7230 | O16: =VLOOKUP($B16,'[2]pop-2020-2023'!$I$5:$M$1126,3) -> 7281 | P16: =VLOOKUP($B16,'[2]pop-2020-2023'!$I$5:$M$1126,4) -> 7341 | Q16: =VLOOKUP($B16,'[2]pop-2020-2023'!$I$5:$M$1126,5) -> 7433 | R16: =VLOOKUP($B16,'[3]Hogares total'!$D$5:$L$1126,6) -> 2363 | S16: =VLOOKUP($B16,'[3]Hogares total'!$D$5:$L$1126,7) -> 2447 | T16: =VLOOKUP($B16,'[3]Hogares total'!$D$5:$L$1126,8) -> 2528 | U16: =VLOOKUP($B16,'[3]Hogares total'!$D$5:$L$1126,9) -> 2611 | W16: =+$E16/O16 -> 0.11907705 | X16: =+$I16/P16 -> 0.11755892 | Y16: =+$M16/Q16 -> 0.11327862 | AA16: =+$E16/S16 -> 0.3543114 | AB16: =+$I16/T16 -> 0.34137658 | AC16: =+$M16/U16 -> 0.32248181 | AD16: =IF(AC16<=0.2,U16,"") | AE16: =IF(AC16<=0.2,M16,"") | AF16: =IF(AC16<=0.2,AD16-AE16,"") | AG16: =IF(AC16>100%,C16,"")
... B585: 27077 | C585: =VLOOKUP(B585,[2]Municipal!$C$15:$D$60549,2) -> Bajo Baudó | D585: =+[1]Total!B586 -> 118 | E585: =+[1]Total!C586 -> 148 | F585: =+[1]Total!D586 -> 216 | G585: =+[1]Total!E586 -> 229 | H585: =+[1]Total!G586 -> 261 | I585: =+[1]Total!H586 -> 267 | J585: =+[1]Total!I586 -> 332 | K585: =+[1]Total!J586 -> 359 | L585: =+[1]Total!L586 -> 323 | M585: =+[1]Total!M586 -> 338 | N585: =VLOOKUP($B585,'[2]pop-2020-2023'!$I$5:$M$1126,2) -> 31444 | O585: =VLOOKUP($B585,'[2]pop-2020-2023'!$I$5:$M$1126,3) -> 32059 | P585: =VLOOKUP($B585,'[2]pop-2020-2023'!$I$5:$M$1126,4) -> 32640 | Q585: =VLOOKUP($B585,'[2]pop-2020-2023'!$I$5:$M$1126,5) -> 33373 | R585: =VLOOKUP($B585,'[3]Hogares total'!$D$5:$L$1126,6) -> 7937 | S585: =VLOOKUP($B585,'[3]Hogares total'!$D$5:$L$1126,7) -> 8146 | T585: =VLOOKUP($B585,'[3]Hogares total'!$D$5:$L$1126,8) -> 8355 | U585: =VLOOKUP($B585,'[3]Hogares total'!$D$5:$L$1126,9) -> 8558 | W585: =+$E585/O585 -> 0.0046164883 | X585: =+$I585/P585 -> 0.0081801471 | Y585: =+$M585/Q585 -> 0.010127948 | AA585: =+$E585/S585 -> 0.018168426 | AB585: =+$I585/T585 -> 0.031956912 | AC585: =+$M585/U585 -> 0.039495209 | AD585: =IF(AC585<=0.2,U585,"") -> 8558 | AE585: =IF(AC585<=0.2,M585,"") -> 338 | AF585: =IF(AC585<=0.2,AD585-AE585,"") -> 8220 | AG585: =IF(AC585>100%,C585,"")
B586: 27086 | C586: =VLOOKUP(B586,[2]Municipal!$C$15:$D$60549,2) -> Bajo Baudó | D586: =+[1]Total!B587 -> 2 | E586: =+[1]Total!C587 -> 2 | F586: =+[1]Total!D587 -> 0 | G586: =+[1]Total!E587 -> 0 | H586: =+[1]Total!G587 -> 0 | I586: =+[1]Total!H587 -> 0 | J586: =+[1]Total!I587 -> 0 | K586: =+[1]Total!J587 -> 0 | L586: =+[1]Total!L587 -> 0 | M586: =+[1]Total!M587 -> 0 | AD586: =IF(AC586<=0.2,U586,"") -> 0 | AE586: =IF(AC586<=0.2,M586,"") -> 0 | AF586: =IF(AC586<=0.2,AD586-AE586,"") -> 0 | AG586: =IF(AC586>100%,C586,"")
B587: 27099 | C587: =VLOOKUP(B587,[2]Municipal!$C$15:$D$60549,2) -> Bojayá | D587: =+[1]Total!B588 -> 144 | E587: =+[1]Total!C588 -> 199 | F587: =+[1]Total!D588 -> 182 | G587: =+[1]Total!E588 -> 203 | H587: =+[1]Total!G588 -> 173 | I587: =+[1]Total!H588 -> 128 | J587: =+[1]Total!I588 -> 184 | K587: =+[1]Total!J588 -> 168 | L587: =+[1]Total!L588 -> 139 | M587: =+[1]Total!M588 -> 156 | N587: =VLOOKUP($B587,'[2]pop-2020-2023'!$I$5:$M$1126,2) -> 12709 | O587: =VLOOKUP($B587,'[2]pop-2020-2023'!$I$5:$M$1126,3) -> 12982 | P587: =VLOOKUP($B587,'[2]pop-2020-2023'!$I$5:$M$1126,4) -> 13210 | Q587: =VLOOKUP($B587,'[2]pop-2020-2023'!$I$5:$M$1126,5) -> 13479 | R587: =VLOOKUP($B587,'[3]Hogares total'!$D$5:$L$1126,6) -> 3395 | S587: =VLOOKUP($B587,'[3]Hogares total'!$D$5:$L$1126,7) -> 3480 | T587: =VLOOKUP($B587,'[3]Hogares total'!$D$5:$L$1126,8) -> 3564 | U587: =VLOOKUP($B587,'[3]Hogares total'!$D$5:$L$1126,9) -> 3646 | W587: =+$E587/O587 -> 0.015328917 | X587: =+$I587/P587 -> 0.0096896291 | Y587: =+$M587/Q587 -> 0.011573559 | AA587: =+$E587/S587 -> 0.057183908 | AB587: =+$I587/T587 -> 0.035914703 | AC587: =+$M587/U587 -> 0.042786615 | AD587: =IF(AC587<=0.2,U587,"") -> 3646 | AE587: =IF(AC587<=0.2,M587,"") -> 156 | AF587: =IF(AC587<=0.2,AD587-AE587,"") -> 3490 | AG587: =IF(AC587>100%,C587,"")
B588: 27135 | C588: =VLOOKUP(B588,[2]Municipal!$C$15:$D$60549,2) -> El Cantón del San Pablo | D588: =+[1]Total!B589 -> 16 | E588: =+[1]Total!C589 -> 18 | F588: =+[1]Total!D589 -> 19 | G588: =+[1]Total!E589 -> 21 | H588: =+[1]Total!G589 -> 20 | I588: =+[1]Total!H589 -> 20 | J588: =+[1]Total!I589 -> 24 | K588: =+[1]Total!J589 -> 21 | L588: =+[1]Total!L589 -> 23 | M588: =+[1]Total!M589 -> 11 | N588: =VLOOKUP($B588,'[2]pop-2020-2023'!$I$5:$M$1126,2) -> 6404 | O588: =VLOOKUP($B588,'[2]pop-2020-2023'!$I$5:$M$1126,3) -> 6521 | P588: =VLOOKUP($B588,'[2]pop-2020-2023'!$I$5:$M$1126,4) -> 6668 | Q588: =VLOOKUP($B588,'[2]pop-2020-2023'!$I$5:$M$1126,5) -> 6783 | R588: =VLOOKUP($B588,'[3]Hogares total'!$D$5:$L$1126,6) -> 2082 | S588: =VLOOKUP($B588,'[3]Hogares total'!$D$5:$L$1126,7) -> 2142 | T588: =VLOOKUP($B588,'[3]Hogares total'!$D$5:$L$1126,8) -> 2201 | U588: =VLOOKUP($B588,'[3]Hogares total'!$D$5:$L$1126,9) -> 2261 | W588: =+$E588/O588 -> 0.0027603128 | X588: =+$I588/P588 -> 0.0029994001 | Y588: =+$M588/Q588 -> 0.0016217013 | AA588: =+$E588/S588 -> 0.0084033613 | AB588: =+$I588/T588 -> 0.0090867787 | AC588: =+$M588/U588 -> 0.0048651039 | AD588: =IF(AC588<=0.2,U588,"") -> 2261 | AE588: =IF(AC588<=0.2,M588,"") -> 11 | AF588: =IF(AC588<=0.2,AD588-AE588,"") -> 2250 | AG588: =IF(AC588>100%,C588,"")
B589: 27150 | C589: =VLOOKUP(B589,[2]Municipal!$C$15:$D$60549,2) -> Carmen del Darién | D589: =+[1]Total!B590 -> 124 | E589: =+[1]Total!C590 -> 134 | F589: =+[1]Total!D590 -> 154 | G589: =+[1]Total!E590 -> 160 | H589: =+[1]Total!G590 -> 172 | I589: =+[1]Total!H590 -> 168 | J589: =+[1]Total!I590 -> 170 | K589: =+[1]Total!J590 -> 156 | L589: =+[1]Total!L590 -> 132 | M589: =+[1]Total!M590 -> 123 | N589: =VLOOKUP($B589,'[2]pop-2020-2023'!$I$5:$M$1126,2) -> 20276 | O589: =VLOOKUP($B589,'[2]pop-2020-2023'!$I$5:$M$1126,3) -> 21107 | P589: =VLOOKUP($B589,'[2]pop-2020-2023'!$I$5:$M$1126,4) -> 21458 | Q589: =VLOOKUP($B589,'[2]pop-2020-2023'!$I$5:$M$1126,5) -> 21814 | R589: =VLOOKUP($B589,'[3]Hogares total'!$D$5:$L$1126,6) -> 6136 | S589: =VLOOKUP($B589,'[3]Hogares total'!$D$5:$L$1126,7) -> 6302 | T589: =VLOOKUP($B589,'[3]Hogares total'!$D$5:$L$1126,8) -> 6467 | U589: =VLOOKUP($B589,'[3]Hogares total'!$D$5:$L$1126,9) -> 6629 | W589: =+$E589/O589 -> 0.0063486047 | X589: =+$I589/P589 -> 0.0078292478 | Y589: =+$M589/Q589 -> 0.0056385807 | AA589: =+$E589/S589 -> 0.021263091 | AB589: =+$I589/T589 -> 0.025978042 | AC589: =+$M589/U589 -> 0.018554835 | AD589: =IF(AC589<=0.2,U589,"") -> 6629 | AE589: =IF(AC589<=0.2,M589,"") -> 123 | AF589: =IF(AC589<=0.2,AD589-AE589,"") -> 6506 | AG589: =IF(AC589>100%,C589,"")
B590: 27160 | C590: =VLOOKUP(B590,[2]Municipal!$C$15:$D$60549,2) -> Cértegui | D590: =+[1]Total!B591 -> 9 | E590: =+[1]Total!C591 -> 176 | F590: =+[1]Total!D591 -> 177 | G590: =+[1]Total!E591 -> 181 | H590: =+[1]Total!G591 -> 181 | I590: =+[1]Total!H591 -> 180 | J590: =+[1]Total!I591 -> 185 | K590: =+[1]Total!J591 -> 179 | L590: =+[1]Total!L591 -> 178 | M590: =+[1]Total!M591 -> 1 | N590: =VLOOKUP($B590,'[2]pop-2020-2023'!$I$5:$M$1126,2) -> 5798 | O590: =VLOOKUP($B590,'[2]pop-2020-2023'!$I$5:$M$1126,3) -> 5864 | P590: =VLOOKUP($B590,'[2]pop-2020-2023'!$I$5:$M$1126,4) -> 5967 | Q590: =VLOOKUP($B590,'[2]pop-2020-2023'!$I$5:$M$1126,5) -> 6088 | R590: =VLOOKUP($B590,'[3]Hogares total'!$D$5:$L$1126,6) -> 2180 | S590: =VLOOKUP($B590,'[3]Hogares total'!$D$5:$L$1126,7) -> 2245 | T590: =VLOOKUP($B590,'[3]Hogares total'!$D$5:$L$1126,8) -> 2311 | U590: =VLOOKUP($B590,'[3]Hogares total'!$D$5:$L$1126,9) -> 2372 | W590: =+$E590/O590 -> 0.030013643 | X590: =+$I590/P590 -> 0.030165913 | Y590: =+$M590/Q590 -> 0.00016425756 | AA590: =+$E590/S590 -> 0.078396437 | AB590: =+$I590/T590 -> 0.07788836 | AC590: =+$M590/U590 -> 0.00042158516 | AD590: =IF(AC590<=0.2,U590,"") -> 2372 | AE590: =IF(AC590<=0.2,M590,"") -> 1 | AF590: =IF(AC590<=0.2,AD590-AE590,"") -> 2371 | AG590: =IF(AC590>100%,C590,"")
B591: 27205 | C591: =VLOOKUP(B591,[2]Municipal!$C$15:$D$60549,2) -> Condoto | D591: =+[1]Total!B592 -> 551 | E591: =+[1]Total!C592 -> 1089 | F591: =+[1]Total!D592 -> 996 | G591: =+[1]Total!E592 -> 1043 | H591: =+[1]Total!G592 -> 1015 | I591: =+[1]Total!H592 -> 970 | J591: =+[1]Total!I592 -> 904 | K591: =+[1]Total!J592 -> 903 | L591: =+[1]Total!L592 -> 811 | M591: =+[1]Total!M592 -> 329 | N591: =VLOOKUP($B591,'[2]pop-2020-2023'!$I$5:$M$1126,2) -> 13068 | O591: =VLOOKUP($B591,'[2]pop-2020-2023'!$I$5:$M$1126,3) -> 13234 | P591: =VLOOKUP($B591,'[2]pop-2020-2023'!$I$5:$M$1126,4) -> 13513 | Q591: =VLOOKUP($B591,'[2]pop-2020-2023'!$I$5:$M$1126,5) -> 13652 | R591: =VLOOKUP($B591,'[3]Hogares total'!$D$5:$L$1126,6) -> 4011 | S591: =VLOOKUP($B591,'[3]Hogares total'!$D$5:$L$1126,7) -> 4130 | T591: =VLOOKUP($B591,'[3]Hogares total'!$D$5:$L$1126,8) -> 4250 | U591: =VLOOKUP($B591,'[3]Hogares total'!$D$5:$L$1126,9) -> 4368 | W591: =+$E591/O591 -> 0.082288046 | X591: =+$I591/P591 -> 0.071782728 | Y591: =+$M591/Q591 -> 0.024099033 | AA591: =+$E591/S591 -> 0.26368039 | AB591: =+$I591/T591 -> 0.22823529 | AC591: =+$M591/U591 -> 0.075320513 | AD591: =IF(AC591<=0.2,U591,"") -> 4368 | AE591: =IF(AC591<=0.2,M591,"") -> 329 | AF591: =IF(AC591<=0.2,AD591-AE591,"") -> 4039 | AG591: =IF(AC591>100%,C591,"")
B592: 27245 | C592: =VLOOKUP(B592,[2]Municipal!$C$15:$D$60549,2) -> El Carmen de Atrato | D592: =+[1]Total!B593 -> 63 | E592: =+[1]Total!C593 -> 139 | F592: =+[1]Total!D593 -> 73 | G592: =+[1]Total!E593 -> 139 | H592: =+[1]Total!G593 -> 78 | I592: =+[1]Total!H593 -> 155 | J592: =+[1]Total!I593 -> 158 | K592: =+[1]Total!J593 -> 152 | L592: =+[1]Total!L593 -> 144 | M592: =+[1]Total!M593 -> 246 | N592: =VLOOKUP($B592,'[2]pop-2020-2023'!$I$5:$M$1126,2) -> 8606 | O592: =VLOOKUP($B592,'[2]pop-2020-2023'!$I$5:$M$1126,3) -> 8770 | P592: =VLOOKUP($B592,'[2]pop-2020-2023'!$I$5:$M$1126,4) -> 8932 | Q592: =VLOOKUP($B592,'[2]pop-2020-2023'!$I$5:$M$1126,5) -> 9121 | R592: =VLOOKUP($B592,'[3]Hogares total'!$D$5:$L$1126,6) -> 2665 | S592: =VLOOKUP($B592,'[3]Hogares total'!$D$5:$L$1126,7) -> 2732 | T592: =VLOOKUP($B592,'[3]Hogares total'!$D$5:$L$1126,8) -> 2800 | U592: =VLOOKUP($B592,'[3]Hogares total'!$D$5:$L$1126,9) -> 2868 | W592: =+$E592/O592 -> 0.015849487 | X592: =+$I592/P592 -> 0.017353336 | Y592: =+$M592/Q592 -> 0.026970727 | AA592: =+$E592/S592 -> 0.050878477 | AB592: =+$I592/T592 -> 0.055357143 | AC592: =+$M592/U592 -> 0.085774059 | AD592: =IF(AC592<=0.2,U592,"") -> 2868 | AE592: =IF(AC592<=0.2,M592,"") -> 246 | AF592: =IF(AC592<=0.2,AD592-AE592,"") -> 2622 | AG592: =IF(AC592>100%,C592,"")
B593: 27250 | C593: =VLOOKUP(B593,[2]Municipal!$C$15:$D$60549,2) -> El Litoral del San Juan | D593: =+[1]Total!B594 -> 94 | E593: =+[1]Total!C594 -> 88 | F593: =+[1]Total!D594 -> 97 | G593: =+[1]Total!E594 -> 96 | H593: =+[1]Total!G594 -> 99 | I593: =+[1]Total!H594 -> 97 | J593: =+[1]Total!I594 -> 109 | K593: =+[1]Total!J594 -> 102 | L593: =+[1]Total!L594 -> 92 | M593: =+[1]Total!M594 -> 96 | N593: =VLOOKUP($B593,'[2]pop-2020-2023'!$I$5:$M$1126,2) -> 23345 | O593: =VLOOKUP($B593,'[2]pop-2020-2023'!$I$5:$M$1126,3) -> 24088 | P593: =VLOOKUP($B593,'[2]pop-2020-2023'!$I$5:$M$1126,4) -> 24533 | Q593: =VLOOKUP($B593,'[2]pop-2020-2023'!$I$5:$M$1126,5) -> 24967 | R593: =VLOOKUP($B593,'[3]Hogares total'!$D$5:$L$1126,6) -> 6109 | S593: =VLOOKUP($B593,'[3]Hogares total'!$D$5:$L$1126,7) -> 6265 | T593: =VLOOKUP($B593,'[3]Hogares total'!$D$5:$L$1126,8) -> 6419 | U593: =VLOOKUP($B593,'[3]Hogares total'!$D$5:$L$1126,9) -> 6573 | W593: =+$E593/O593 -> 0.0036532713 | X593: =+$I593/P593 -> 0.0039538581 | Y593: =+$M593/Q593 -> 0.0038450755 | AA593: =+$E593/S593 -> 0.014046289 | AB593: =+$I593/T593 -> 0.015111388 | AC593: =+$M593/U593 -> 0.014605203 | AD593: =IF(AC593<=0.2,U593,"") -> 6573 | AE593: =IF(AC593<=0.2,M593,"") -> 96 | AF593: =IF(AC593<=0.2,AD593-AE593,"") -> 6477 | AG593: =IF(AC593>100%,C593,"")
B594: 27361 | C594: =VLOOKUP(B594,[2]Municipal!$C$15:$D$60549,2) -> Istmina | D594: =+[1]Total!B595 -> 2913 | E594: =+[1]Total!C595 -> 2892 | F594: =+[1]Total!D595 -> 2809 | G594: =+[1]Total!E595 -> 2774 | H594: =+[1]Total!G595 -> 2718 | I594: =+[1]Total!H595 -> 2556 | J594: =+[1]Total!I595 -> 3554 | K594: =+[1]Total!J595 -> 3208 | L594: =+[1]Total!L595 -> 2795 | M594: =+[1]Total!M595 -> 2604 | N594: =VLOOKUP($B594,'[2]pop-2020-2023'!$I$5:$M$1126,2) -> 31772 | O594: =VLOOKUP($B594,'[2]pop-2020-2023'!$I$5:$M$1126,3) -> 32170 | P594: =VLOOKUP($B594,'[2]pop-2020-2023'!$I$5:$M$1126,4) -> 32809 | Q594: =VLOOKUP($B594,'[2]pop-2020-2023'!$I$5:$M$1126,5) -> 33188 | R594: =VLOOKUP($B594,'[3]Hogares total'!$D$5:$L$1126,6) -> 9333 | S594: =VLOOKUP($B594,'[3]Hogares total'!$D$5:$L$1126,7) -> 9605 | T594: =VLOOKUP($B594,'[3]Hogares total'!$D$5:$L$1126,8) -> 9879 | U594: =VLOOKUP($B594,'[3]Hogares total'!$D$5:$L$1126,9) -> 10147 | W594: =+$E594/O594 -> 0.08989742 | X594: =+$I594/P594 -> 0.077905453 | Y594: =+$M594/Q594 -> 0.078462095 | AA594: =+$E594/S594 -> 0.30109318 | AB594: =+$I594/T594 -> 0.25873064 | AC594: =+$M594/U594 -> 0.25662757 | AD594: =IF(AC594<=0.2,U594,"") | AE594: =IF(AC594<=0.2,M594,"") | AF594: =IF(AC594<=0.2,AD594-AE594,"") | AG594: =IF(AC594>100%,C594,"")
B595: 27372 | C595: =VLOOKUP(B595,[2]Municipal!$C$15:$D$60549,2) -> Juradó | D595: =+[1]Total!B596 -> 160 | E595: =+[1]Total!C596 -> 160 | F595: =+[1]Total!D596 -> 168 | G595: =+[1]Total!E596 -> 146 | H595: =+[1]Total!G596 -> 173 | I595: =+[1]Total!H596 -> 156 | J595: =+[1]Total!I596 -> 154 | K595: =+[1]Total!J596 -> 142 | L595: =+[1]Total!L596 -> 142 | M595: =+[1]Total!M596 -> 129 | N595: =VLOOKUP($B595,'[2]pop-2020-2023'!$I$5:$M$1126,2) -> 7032 | O595: =VLOOKUP($B595,'[2]pop-2020-2023'!$I$5:$M$1126,3) -> 7153 | P595: =VLOOKUP($B595,'[2]pop-2020-2023'!$I$5:$M$1126,4) -> 7274 | Q595: =VLOOKUP($B595,'[2]pop-2020-2023'!$I$5:$M$1126,5) -> 7408 | R595: =VLOOKUP($B595,'[3]Hogares total'!$D$5:$L$1126,6) -> 1801 | S595: =VLOOKUP($B595,'[3]Hogares total'!$D$5:$L$1126,7) -> 1849 | T595: =VLOOKUP($B595,'[3]Hogares total'!$D$5:$L$1126,8) -> 1896 | U595: =VLOOKUP($B595,'[3]Hogares total'!$D$5:$L$1126,9) -> 1944 | W595: =+$E595/O595 -> 0.022368237 | X595: =+$I595/P595 -> 0.021446247 | Y595: =+$M595/Q595 -> 0.017413607 | AA595: =+$E595/S595 -> 0.086533261 | AB595: =+$I595/T595 -> 0.082278481 | AC595: =+$M595/U595 -> 0.066358025 | AD595: =IF(AC595<=0.2,U595,"") -> 1944 | AE595: =IF(AC595<=0.2,M595,"") -> 129 | AF595: =IF(AC595<=0.2,AD595-AE595,"") -> 1815 | AG595: =IF(AC595>100%,C595,"")
B596: 27413 | C596: =VLOOKUP(B596,[2]Municipal!$C$15:$D$60549,2) -> Lloró | D596: =+[1]Total!B597 -> 16 | E596: =+[1]Total!C597 -> 13 | F596: =+[1]Total!D597 -> 12 | G596: =+[1]Total!E597 -> 11 | H596: =+[1]Total!G597 -> 15 | I596: =+[1]Total!H597 -> 13 | J596: =+[1]Total!I597 -> 21 | K596: =+[1]Total!J597 -> 21 | L596: =+[1]Total!L597 -> 20 | M596: =+[1]Total!M597 -> 11 | N596: =VLOOKUP($B596,'[2]pop-2020-2023'!$I$5:$M$1126,2) -> 10022 | O596: =VLOOKUP($B596,'[2]pop-2020-2023'!$I$5:$M$1126,3) -> 10081 | P596: =VLOOKUP($B596,'[2]pop-2020-2023'!$I$5:$M$1126,4) -> 10265 | Q596: =VLOOKUP($B596,'[2]pop-2020-2023'!$I$5:$M$1126,5) -> 10456 | R596: =VLOOKUP($B596,'[3]Hogares total'!$D$5:$L$1126,6) -> 2871 | S596: =VLOOKUP($B596,'[3]Hogares total'!$D$5:$L$1126,7) -> 2948 | T596: =VLOOKUP($B596,'[3]Hogares total'!$D$5:$L$1126,8) -> 3026 | U596: =VLOOKUP($B596,'[3]Hogares total'!$D$5:$L$1126,9) -> 3102 | W596: =+$E596/O596 -> 0.0012895546 | X596: =+$I596/P596 -> 0.0012664394 | Y596: =+$M596/Q596 -> 0.0010520275 | AA596: =+$E596/S596 -> 0.0044097693 | AB596: =+$I596/T596 -> 0.0042961005 | AC596: =+$M596/U596 -> 0.0035460993 | AD596: =IF(AC596<=0.2,U596,"") -> 3102 | AE596: =IF(AC596<=0.2,M596,"") -> 11 | AF596: =IF(AC596<=0.2,AD596-AE596,"") -> 3091 | AG596: =IF(AC596>100%,C596,"")
B597: 27425 | C597: =VLOOKUP(B597,[2]Municipal!$C$15:$D$60549,2) -> Medio Atrato | D597: =+[1]Total!B598 -> 16 | E597: =+[1]Total!C598 -> 21 | F597: =+[1]Total!D598 -> 34 | G597: =+[1]Total!E598 -> 35 | H597: =+[1]Total!G598 -> 34 | I597: =+[1]Total!H598 -> 34 | J597: =+[1]Total!I598 -> 32 | K597: =+[1]Total!J598 -> 32 | L597: =+[1]Total!L598 -> 31 | M597: =+[1]Total!M598 -> 32 | N597: =VLOOKUP($B597,'[2]pop-2020-2023'!$I$5:$M$1126,2) -> 11759 | O597: =VLOOKUP($B597,'[2]pop-2020-2023'!$I$5:$M$1126,3) -> 12252 | P597: =VLOOKUP($B597,'[2]pop-2020-2023'!$I$5:$M$1126,4) -> 12467 | Q597: =VLOOKUP($B597,'[2]pop-2020-2023'!$I$5:$M$1126,5) -> 12668 | R597: =VLOOKUP($B597,'[3]Hogares total'!$D$5:$L$1126,6) -> 3511 | S597: =VLOOKUP($B597,'[3]Hogares total'!$D$5:$L$1126,7) -> 3600 | T597: =VLOOKUP($B597,'[3]Hogares total'!$D$5:$L$1126,8) -> 3685 | U597: =VLOOKUP($B597,'[3]Hogares total'!$D$5:$L$1126,9) -> 3772 | W597: =+$E597/O597 -> 0.0017140059 | X597: =+$I597/P597 -> 0.0027271998 | Y597: =+$M597/Q597 -> 0.0025260499 | AA597: =+$E597/S597 -> 0.0058333333 | AB597: =+$I597/T597 -> 0.0092265943 | AC597: =+$M597/U597 -> 0.0084835631 | AD597: =IF(AC597<=0.2,U597,"") -> 3772 | AE597: =IF(AC597<=0.2,M597,"") -> 32 | AF597: =IF(AC597<=0.2,AD597-AE597,"") -> 3740 | AG597: =IF(AC597>100%,C597,"")
B598: 27430 | C598: =VLOOKUP(B598,[2]Municipal!$C$15:$D$60549,2) -> Medio Baudó | D598: =+[1]Total!B599 -> 27 | E598: =+[1]Total!C599 -> 30 | F598: =+[1]Total!D599 -> 34 | G598: =+[1]Total!E599 -> 38 | H598: =+[1]Total!G599 -> 37 | I598: =+[1]Total!H599 -> 33 | J598: =+[1]Total!I599 -> 42 | K598: =+[1]Total!J599 -> 42 | L598: =+[1]Total!L599 -> 43 | M598: =+[1]Total!M599 -> 33 | N598: =VLOOKUP($B598,'[2]pop-2020-2023'!$I$5:$M$1126,2) -> 15765 | O598: =VLOOKUP($B598,'[2]pop-2020-2023'!$I$5:$M$1126,3) -> 16058 | P598: =VLOOKUP($B598,'[2]pop-2020-2023'!$I$5:$M$1126,4) -> 16340 | Q598: =VLOOKUP($B598,'[2]pop-2020-2023'!$I$5:$M$1126,5) -> 16632 | R598: =VLOOKUP($B598,'[3]Hogares total'!$D$5:$L$1126,6) -> 4742 | S598: =VLOOKUP($B598,'[3]Hogares total'!$D$5:$L$1126,7) -> 4870 | T598: =VLOOKUP($B598,'[3]Hogares total'!$D$5:$L$1126,8) -> 4995 | U598: =VLOOKUP($B598,'[3]Hogares total'!$D$5:$L$1126,9) -> 5121 | W598: =+$E598/O598 -> 0.0018682277 | X598: =+$I598/P598 -> 0.0020195838 | Y598: =+$M598/Q598 -> 0.001984127 | AA598: =+$E598/S598 -> 0.0061601643 | AB598: =+$I598/T598 -> 0.0066066066 | AC598: =+$M598/U598 -> 0.0064440539 | AD598: =IF(AC598<=0.2,U598,"") -> 5121 | AE598: =IF(AC598<=0.2,M598,"") -> 33 | AF598: =IF(AC598<=0.2,AD598-AE598,"") -> 5088 | AG598: =IF(AC598>100%,C598,"")
... B1098: 91430 | C1098: =VLOOKUP(B1098,[2]Municipal!$C$15:$D$60549,2) -> La Victoria (CD) | D1098: =+[1]Total!B1099 -> 229 | E1098: =+[1]Total!C1099 -> 1 | F1098: =+[1]Total!D1099 -> 1 | G1098: =+[1]Total!E1099 -> 1 | H1098: =+[1]Total!G1099 -> 0 | I1098: =+[1]Total!H1099 -> 0 | J1098: =+[1]Total!I1099 -> 0 | K1098: =+[1]Total!J1099 -> 0 | L1098: =+[1]Total!L1099 -> 0 | M1098: =+[1]Total!M1099 -> 0 | N1098: =VLOOKUP($B1098,'[2]pop-2020-2023'!$I$5:$M$1126,2) -> 658 | O1098: =VLOOKUP($B1098,'[2]pop-2020-2023'!$I$5:$M$1126,3) -> 654 | P1098: =VLOOKUP($B1098,'[2]pop-2020-2023'!$I$5:$M$1126,4) -> 668 | Q1098: =VLOOKUP($B1098,'[2]pop-2020-2023'!$I$5:$M$1126,5) -> 685 | R1098: =VLOOKUP($B1098,'[3]Hogares total'!$D$5:$L$1126,6) -> 173 | S1098: =VLOOKUP($B1098,'[3]Hogares total'!$D$5:$L$1126,7) -> 176 | T1098: =VLOOKUP($B1098,'[3]Hogares total'!$D$5:$L$1126,8) -> 181 | U1098: =VLOOKUP($B1098,'[3]Hogares total'!$D$5:$L$1126,9) -> 185 | W1098: =+$E1098/O1098 -> 0.001529052 | X1098: =+$I1098/P1098 -> 0 | Y1098: =+$M1098/Q1098 -> 0 | AA1098: =+$E1098/S1098 -> 0.0056818182 | AB1098: =+$I1098/T1098 -> 0 | AC1098: =+$M1098/U1098 -> 0 | AD1098: =IF(AC1098<=0.2,U1098,"") -> 185 | AE1098: =IF(AC1098<=0.2,M1098,"") -> 0 | AF1098: =IF(AC1098<=0.2,AD1098-AE1098,"") -> 185 | AG1098: =IF(AC1098>100%,C1098,"")
B1099: 91460 | N1099: =+'[2]pop-2020-2023'!J1098 -> 1867 | O1099: =+'[2]pop-2020-2023'!K1098 -> 1857 | P1099: =+'[2]pop-2020-2023'!L1098 -> 1887 | Q1099: =+'[2]pop-2020-2023'!M1098 -> 1910 | R1099: =VLOOKUP($B1099,'[3]Hogares total'!$D$5:$L$1126,6) -> 355 | S1099: =VLOOKUP($B1099,'[3]Hogares total'!$D$5:$L$1126,7) -> 363 | T1099: =VLOOKUP($B1099,'[3]Hogares total'!$D$5:$L$1126,8) -> 370 | U1099: =VLOOKUP($B1099,'[3]Hogares total'!$D$5:$L$1126,9) -> 379 | W1099: =+$E1099/O1099 -> 0 | X1099: =+$I1099/P1099 -> 0 | Y1099: =+$M1099/Q1099 -> 0 | AA1099: =+$E1099/S1099 -> 0 | AB1099: =+$I1099/T1099 -> 0 | AC1099: =+$M1099/U1099 -> 0 | AD1099: =IF(AC1099<=0.2,U1099,"") -> 379 | AE1099: =IF(AC1099<=0.2,M1099,"") -> 0 | AF1099: =IF(AC1099<=0.2,AD1099-AE1099,"") -> 379 | AG1099: =IF(AC1099>100%,C1099,"")
B1100: 91530 | C1100: =VLOOKUP(B1100,[2]Municipal!$C$15:$D$60549,2) -> Puerto Alegría (CD) | D1100: =+[1]Total!B1100 -> 0 | E1100: =+[1]Total!C1100 -> 0 | F1100: =+[1]Total!D1100 -> 1 | G1100: =+[1]Total!E1100 -> 1 | H1100: =+[1]Total!G1100 -> 0 | I1100: =+[1]Total!H1100 -> 0 | J1100: =+[1]Total!I1100 -> 0 | K1100: =+[1]Total!J1100 -> 2 | L1100: =+[1]Total!L1100 -> 1 | M1100: =+[1]Total!M1100 -> 3 | N1100: =VLOOKUP($B1100,'[2]pop-2020-2023'!$I$5:$M$1126,2) -> 754 | O1100: =VLOOKUP($B1100,'[2]pop-2020-2023'!$I$5:$M$1126,3) -> 758 | P1100: =VLOOKUP($B1100,'[2]pop-2020-2023'!$I$5:$M$1126,4) -> 774 | Q1100: =VLOOKUP($B1100,'[2]pop-2020-2023'!$I$5:$M$1126,5) -> 782 | R1100: =VLOOKUP($B1100,'[3]Hogares total'!$D$5:$L$1126,6) -> 200 | S1100: =VLOOKUP($B1100,'[3]Hogares total'!$D$5:$L$1126,7) -> 203 | T1100: =VLOOKUP($B1100,'[3]Hogares total'!$D$5:$L$1126,8) -> 205 | U1100: =VLOOKUP($B1100,'[3]Hogares total'!$D$5:$L$1126,9) -> 210 | W1100: =+$E1100/O1100 -> 0 | X1100: =+$I1100/P1100 -> 0 | Y1100: =+$M1100/Q1100 -> 0.0038363171 | AA1100: =+$E1100/S1100 -> 0 | AB1100: =+$I1100/T1100 -> 0 | AC1100: =+$M1100/U1100 -> 0.014285714 | AD1100: =IF(AC1100<=0.2,U1100,"") -> 210 | AE1100: =IF(AC1100<=0.2,M1100,"") -> 3 | AF1100: =IF(AC1100<=0.2,AD1100-AE1100,"") -> 207 | AG1100: =IF(AC1100>100%,C1100,"")
B1101: 91536 | C1101: =VLOOKUP(B1101,[2]Municipal!$C$15:$D$60549,2) -> Puerto Arica (CD) | D1101: =+[1]Total!B1101 -> 4 | E1101: =+[1]Total!C1101 -> 3 | F1101: =+[1]Total!D1101 -> 4 | G1101: =+[1]Total!E1101 -> 2 | H1101: =+[1]Total!G1101 -> 3 | I1101: =+[1]Total!H1101 -> 3 | J1101: =+[1]Total!I1101 -> 1 | K1101: =+[1]Total!J1101 -> 3 | L1101: =+[1]Total!L1101 -> 3 | M1101: =+[1]Total!M1101 -> 4 | N1101: =VLOOKUP($B1101,'[2]pop-2020-2023'!$I$5:$M$1126,2) -> 1031 | O1101: =VLOOKUP($B1101,'[2]pop-2020-2023'!$I$5:$M$1126,3) -> 1045 | P1101: =VLOOKUP($B1101,'[2]pop-2020-2023'!$I$5:$M$1126,4) -> 1076 | Q1101: =VLOOKUP($B1101,'[2]pop-2020-2023'!$I$5:$M$1126,5) -> 1089 | R1101: =VLOOKUP($B1101,'[3]Hogares total'!$D$5:$L$1126,6) -> 305 | S1101: =VLOOKUP($B1101,'[3]Hogares total'!$D$5:$L$1126,7) -> 312 | T1101: =VLOOKUP($B1101,'[3]Hogares total'!$D$5:$L$1126,8) -> 319 | U1101: =VLOOKUP($B1101,'[3]Hogares total'!$D$5:$L$1126,9) -> 327 | W1101: =+$E1101/O1101 -> 0.0028708134 | X1101: =+$I1101/P1101 -> 0.0027881041 | Y1101: =+$M1101/Q1101 -> 0.0036730946 | AA1101: =+$E1101/S1101 -> 0.0096153846 | AB1101: =+$I1101/T1101 -> 0.0094043887 | AC1101: =+$M1101/U1101 -> 0.012232416 | AD1101: =IF(AC1101<=0.2,U1101,"") -> 327 | AE1101: =IF(AC1101<=0.2,M1101,"") -> 4 | AF1101: =IF(AC1101<=0.2,AD1101-AE1101,"") -> 323 | AG1101: =IF(AC1101>100%,C1101,"")
B1102: 91540 | C1102: =VLOOKUP(B1102,[2]Municipal!$C$15:$D$60549,2) -> Puerto Nariño | D1102: =+[1]Total!B1102 -> 37 | E1102: =+[1]Total!C1102 -> 38 | F1102: =+[1]Total!D1102 -> 35 | G1102: =+[1]Total!E1102 -> 36 | H1102: =+[1]Total!G1102 -> 11 | I1102: =+[1]Total!H1102 -> 25 | J1102: =+[1]Total!I1102 -> 15 | K1102: =+[1]Total!J1102 -> 11 | L1102: =+[1]Total!L1102 -> 11 | M1102: =+[1]Total!M1102 -> 10 | N1102: =VLOOKUP($B1102,'[2]pop-2020-2023'!$I$5:$M$1126,2) -> 10234 | O1102: =VLOOKUP($B1102,'[2]pop-2020-2023'!$I$5:$M$1126,3) -> 10418 | P1102: =VLOOKUP($B1102,'[2]pop-2020-2023'!$I$5:$M$1126,4) -> 10587 | Q1102: =VLOOKUP($B1102,'[2]pop-2020-2023'!$I$5:$M$1126,5) -> 10772 | R1102: =VLOOKUP($B1102,'[3]Hogares total'!$D$5:$L$1126,6) -> 2497 | S1102: =VLOOKUP($B1102,'[3]Hogares total'!$D$5:$L$1126,7) -> 2596 | T1102: =VLOOKUP($B1102,'[3]Hogares total'!$D$5:$L$1126,8) -> 2701 | U1102: =VLOOKUP($B1102,'[3]Hogares total'!$D$5:$L$1126,9) -> 2816 | W1102: =+$E1102/O1102 -> 0.0036475331 | X1102: =+$I1102/P1102 -> 0.0023613866 | Y1102: =+$M1102/Q1102 -> 0.00092833271 | AA1102: =+$E1102/S1102 -> 0.014637904 | AB1102: =+$I1102/T1102 -> 0.0092558312 | AC1102: =+$M1102/U1102 -> 0.0035511364 | AD1102: =IF(AC1102<=0.2,U1102,"") -> 2816 | AE1102: =IF(AC1102<=0.2,M1102,"") -> 10 | AF1102: =IF(AC1102<=0.2,AD1102-AE1102,"") -> 2806 | AG1102: =IF(AC1102>100%,C1102,"")
B1103: 91669 | N1103: =+'[2]pop-2020-2023'!J1102 -> 1828 | O1103: =+'[2]pop-2020-2023'!K1102 -> 1864 | P1103: =+'[2]pop-2020-2023'!L1102 -> 1891 | Q1103: =+'[2]pop-2020-2023'!M1102 -> 1921 | R1103: =VLOOKUP($B1103,'[3]Hogares total'!$D$5:$L$1126,6) -> 395 | S1103: =VLOOKUP($B1103,'[3]Hogares total'!$D$5:$L$1126,7) -> 403 | T1103: =VLOOKUP($B1103,'[3]Hogares total'!$D$5:$L$1126,8) -> 412 | U1103: =VLOOKUP($B1103,'[3]Hogares total'!$D$5:$L$1126,9) -> 421 | W1103: =+$E1103/O1103 -> 0 | X1103: =+$I1103/P1103 -> 0 | Y1103: =+$M1103/Q1103 -> 0 | AA1103: =+$E1103/S1103 -> 0 | AB1103: =+$I1103/T1103 -> 0 | AC1103: =+$M1103/U1103 -> 0 | AD1103: =IF(AC1103<=0.2,U1103,"") -> 421 | AE1103: =IF(AC1103<=0.2,M1103,"") -> 0 | AF1103: =IF(AC1103<=0.2,AD1103-AE1103,"") -> 421 | AG1103: =IF(AC1103>100%,C1103,"")
B1104: 91798 | C1104: =VLOOKUP(B1104,[2]Municipal!$C$15:$D$60549,2) -> Tarapacá (CD) | D1104: =+[1]Total!B1103 -> 22 | E1104: =+[1]Total!C1103 -> 19 | F1104: =+[1]Total!D1103 -> 21 | G1104: =+[1]Total!E1103 -> 12 | H1104: =+[1]Total!G1103 -> 19 | I1104: =+[1]Total!H1103 -> 28 | J1104: =+[1]Total!I1103 -> 21 | K1104: =+[1]Total!J1103 -> 25 | L1104: =+[1]Total!L1103 -> 18 | M1104: =+[1]Total!M1103 -> 23 | N1104: =VLOOKUP($B1104,'[2]pop-2020-2023'!$I$5:$M$1126,2) -> 4047 | O1104: =VLOOKUP($B1104,'[2]pop-2020-2023'!$I$5:$M$1126,3) -> 4159 | P1104: =VLOOKUP($B1104,'[2]pop-2020-2023'!$I$5:$M$1126,4) -> 4245 | Q1104: =VLOOKUP($B1104,'[2]pop-2020-2023'!$I$5:$M$1126,5) -> 4314 | R1104: =VLOOKUP($B1104,'[3]Hogares total'!$D$5:$L$1126,6) -> 929 | S1104: =VLOOKUP($B1104,'[3]Hogares total'!$D$5:$L$1126,7) -> 949 | T1104: =VLOOKUP($B1104,'[3]Hogares total'!$D$5:$L$1126,8) -> 970 | U1104: =VLOOKUP($B1104,'[3]Hogares total'!$D$5:$L$1126,9) -> 993 | W1104: =+$E1104/O1104 -> 0.0045684059 | X1104: =+$I1104/P1104 -> 0.0065959953 | Y1104: =+$M1104/Q1104 -> 0.0053314789 | AA1104: =+$E1104/S1104 -> 0.020021075 | AB1104: =+$I1104/T1104 -> 0.028865979 | AC1104: =+$M1104/U1104 -> 0.023162135 | AD1104: =IF(AC1104<=0.2,U1104,"") -> 993 | AE1104: =IF(AC1104<=0.2,M1104,"") -> 23 | AF1104: =IF(AC1104<=0.2,AD1104-AE1104,"") -> 970 | AG1104: =IF(AC1104>100%,C1104,"")
B1105: 94001 | C1105: =VLOOKUP(B1105,[2]Municipal!$C$15:$D$60549,2) -> Inírida | D1105: =+[1]Total!B1104 -> 1510 | E1105: =+[1]Total!C1104 -> 1316 | F1105: =+[1]Total!D1104 -> 1152 | G1105: =+[1]Total!E1104 -> 971 | H1105: =+[1]Total!G1104 -> 701 | I1105: =+[1]Total!H1104 -> 813 | J1105: =+[1]Total!I1104 -> 907 | K1105: =+[1]Total!J1104 -> 764 | L1105: =+[1]Total!L1104 -> 776 | M1105: =+[1]Total!M1104 -> 675 | N1105: =VLOOKUP($B1105,'[2]pop-2020-2023'!$I$5:$M$1126,2) -> 34026 | O1105: =VLOOKUP($B1105,'[2]pop-2020-2023'!$I$5:$M$1126,3) -> 35041 | P1105: =VLOOKUP($B1105,'[2]pop-2020-2023'!$I$5:$M$1126,4) -> 36024 | Q1105: =VLOOKUP($B1105,'[2]pop-2020-2023'!$I$5:$M$1126,5) -> 37015 | R1105: =VLOOKUP($B1105,'[3]Hogares total'!$D$5:$L$1126,6) -> 8665 | S1105: =VLOOKUP($B1105,'[3]Hogares total'!$D$5:$L$1126,7) -> 8973 | T1105: =VLOOKUP($B1105,'[3]Hogares total'!$D$5:$L$1126,8) -> 9263 | U1105: =VLOOKUP($B1105,'[3]Hogares total'!$D$5:$L$1126,9) -> 9560 | W1105: =+$E1105/O1105 -> 0.037556006 | X1105: =+$I1105/P1105 -> 0.022568288 | Y1105: =+$M1105/Q1105 -> 0.01823585 | AA1105: =+$E1105/S1105 -> 0.14666221 | AB1105: =+$I1105/T1105 -> 0.087768542 | AC1105: =+$M1105/U1105 -> 0.070606695 | AD1105: =IF(AC1105<=0.2,U1105,"") -> 9560 | AE1105: =IF(AC1105<=0.2,M1105,"") -> 675 | AF1105: =IF(AC1105<=0.2,AD1105-AE1105,"") -> 8885 | AG1105: =IF(AC1105>100%,C1105,"")
B1106: 94343 | C1106: =VLOOKUP(B1106,[2]Municipal!$C$15:$D$60549,2) -> Barrancominas (CD) | D1106: =+[1]Total!B1105 -> 6 | E1106: =+[1]Total!C1105 -> 6 | F1106: =+[1]Total!D1105 -> 11 | G1106: =+[1]Total!E1105 -> 8 | H1106: =+[1]Total!G1105 -> 10 | I1106: =+[1]Total!H1105 -> 11 | J1106: =+[1]Total!I1105 -> 6 | K1106: =+[1]Total!J1105 -> 15 | L1106: =+[1]Total!L1105 -> 20 | M1106: =+[1]Total!M1105 -> 8 | N1106: =VLOOKUP($B1106,'[2]pop-2020-2023'!$I$5:$M$1126,2) -> 9947 | O1106: =VLOOKUP($B1106,'[2]pop-2020-2023'!$I$5:$M$1126,3) -> 10289 | P1106: =VLOOKUP($B1106,'[2]pop-2020-2023'!$I$5:$M$1126,4) -> 10569 | Q1106: =VLOOKUP($B1106,'[2]pop-2020-2023'!$I$5:$M$1126,5) -> 10815 | R1106: =VLOOKUP($B1106,'[3]Hogares total'!$D$5:$L$1126,6) -> 1354 | S1106: =VLOOKUP($B1106,'[3]Hogares total'!$D$5:$L$1126,7) -> 1372 | T1106: =VLOOKUP($B1106,'[3]Hogares total'!$D$5:$L$1126,8) -> 1390 | U1106: =VLOOKUP($B1106,'[3]Hogares total'!$D$5:$L$1126,9) -> 1408 | W1106: =+$E1106/O1106 -> 0.00058314705 | X1106: =+$I1106/P1106 -> 0.0010407796 | Y1106: =+$M1106/Q1106 -> 0.00073971336 | AA1106: =+$E1106/S1106 -> 0.0043731778 | AB1106: =+$I1106/T1106 -> 0.0079136691 | AC1106: =+$M1106/U1106 -> 0.0056818182 | AD1106: =IF(AC1106<=0.2,U1106,"") -> 1408 | AE1106: =IF(AC1106<=0.2,M1106,"") -> 8 | AF1106: =IF(AC1106<=0.2,AD1106-AE1106,"") -> 1400 | AG1106: =IF(AC1106>100%,C1106,"")
B1107: 94663 | C1107: Mapiripana (CD) | D1107: 0 | E1107: 0 | F1107: 0 | G1107: 0 | H1107: 0 | I1107: 0 | J1107: 0 | K1107: 0 | L1107: 0 | M1107: 0 | N1107: 0 | O1107: 0 | P1107: 0 | Q1107: 0 | R1107: 0 | S1107: 0 | T1107: 0 | U1107: 0 | W1107: =IF(O1107=0,0,$E1107/O1107) -> 0 | X1107: =IF(P1107=0,0,+$I1107/P1107) -> 0 | Y1107: =IF(Q1107=0,0,$M1107/Q1107) -> 0 | AA1107: =IF(S1107=0,0,$E1107/S1107) -> 0 | AB1107: =IF(T1107=0,0,$I1107/T1107) -> 0 | AC1107: =IF(U1107=0,0,$M1107/U1107) -> 0 | AD1107: =IF(AC1107<=0.2,U1107,"") -> 0 | AE1107: =IF(AC1107<=0.2,M1107,"") -> 0 | AF1107: =IF(AC1107<=0.2,AD1107-AE1107,"") -> 0 | AG1107: =IF(AC1107>100%,C1107,"")
...

Sheet Accesos x Municipio-NoCorporati
V1: D E N S I D A D / P E N E T R A C I O N D E I N T E R N E T
D2: A C C E S O S D E I N T E R N E T | N2: P O B L A C I O N | R2: H O G A R E S | V2: S O B R E P O B L A C I O N | Z2: S O B R E H O G A R E S
D3: =+[1]Total!$B$4 -> 2021 | H3: =+[1]Total!$G$4 -> 2022 | L3: 2023 | N3: 2020 | O3: =+N3+1 -> 2021 | P3: =+O3+1 -> 2022 | Q3: =+P3+1 -> 2023 | R3: 2020 | S3: =+R3+1 -> 2021 | T3: =+S3+1 -> 2022 | U3: =+T3+1 -> 2023 | V3: 2020 | W3: =+V3+1 -> 2021 | X3: =+W3+1 -> 2022 | Y3: =+X3+1 -> 2023 | Z3: 2020 | AA3: =+Z3+1 -> 2021 | AB3: =+AA3+1 -> 2022 | AC3: =+AB3+1 -> 2023
C4: Municipio | D4: =+[1]Total!B5 -> 1 | E4: =+[1]Total!C5 -> 2 | F4: =+[1]Total!D5 -> 3 | G4: =+[1]Total!E5 -> 4 | H4: =+[1]Total!G5 -> 1 | I4: =+[1]Total!H5 -> 2 | J4: =+[1]Total!I5 -> 3 | K4: =+[1]Total!J5 -> 4 | L4: =+[1]Total!L5 -> 1 | M4: =+[1]Total!M5 -> 2
B5: 05001 | C5: =VLOOKUP(B5,[2]Municipal!$C$15:$D$60549,2) -> Medellín | D5: =VLOOKUP($B5,'[1]Sin Corporativo'!$Q$6:$AA$1115,2) -> 629451 | E5: =VLOOKUP($B5,'[1]Sin Corporativo'!$Q$6:$AA$1115,3) -> 628745 | F5: =VLOOKUP($B5,'[1]Sin Corporativo'!$Q$6:$AA$1115,4) -> 636827 | G5: =VLOOKUP($B5,'[1]Sin Corporativo'!$Q$6:$AA$1115,5) -> 644738 | H5: =VLOOKUP($B5,'[1]Sin Corporativo'!$Q$6:$AA$1115,6) -> 658682 | I5: =VLOOKUP($B5,'[1]Sin Corporativo'!$Q$6:$AA$1115,7) -> 669364 | J5: =VLOOKUP($B5,'[1]Sin Corporativo'!$Q$6:$AA$1115,8) -> 673935 | K5: =VLOOKUP($B5,'[1]Sin Corporativo'!$Q$6:$AA$1115,9) -> 692550 | L5: =VLOOKUP($B5,'[1]Sin Corporativo'!$Q$6:$AA$1115,10) -> 692168 | M5: =VLOOKUP($B5,'[1]Sin Corporativo'!$Q$6:$AA$1115,11) -> 697999 | N5: =VLOOKUP($B5,'[2]pop-2020-2023'!$I$5:$M$1126,2) -> 2519592 | O5: =VLOOKUP($B5,'[2]pop-2020-2023'!$I$5:$M$1126,3) -> 2549008 | P5: =VLOOKUP($B5,'[2]pop-2020-2023'!$I$5:$M$1126,4) -> 2572350 | Q5: =VLOOKUP($B5,'[2]pop-2020-2023'!$I$5:$M$1126,5) -> 2595300 | R5: =VLOOKUP($B5,'[3]Hogares total'!$D$5:$L$1126,6) -> 878480 | S5: =VLOOKUP($B5,'[3]Hogares total'!$D$5:$L$1126,7) -> 908775 | T5: =VLOOKUP($B5,'[3]Hogares total'!$D$5:$L$1126,8) -> 939966 | U5: =VLOOKUP($B5,'[3]Hogares total'!$D$5:$L$1126,9) -> 972037 | W5: =+$E5/O5 -> 0.24666262 | X5: =+$I5/P5 -> 0.26021498 | Y5: =+$M5/Q5 -> 0.26894733 | AA5: =+$E5/S5 -> 0.69185992 | AB5: =+$I5/T5 -> 0.71211512 | AC5: =+$M5/U5 -> 0.71807863 | AD5: =+T5-K5 -> 247416
B6: 05002 | C6: =VLOOKUP(B6,[2]Municipal!$C$15:$D$60549,2) -> Abejorral | D6: =VLOOKUP($B6,'[1]Sin Corporativo'!$Q$6:$AA$1115,2) -> 2055 | E6: =VLOOKUP($B6,'[1]Sin Corporativo'!$Q$6:$AA$1115,3) -> 2241 | F6: =VLOOKUP($B6,'[1]Sin Corporativo'!$Q$6:$AA$1115,4) -> 2195 | G6: =VLOOKUP($B6,'[1]Sin Corporativo'!$Q$6:$AA$1115,5) -> 2129 | H6: =VLOOKUP($B6,'[1]Sin Corporativo'!$Q$6:$AA$1115,6) -> 2309 | I6: =VLOOKUP($B6,'[1]Sin Corporativo'!$Q$6:$AA$1115,7) -> 2323 | J6: =VLOOKUP($B6,'[1]Sin Corporativo'!$Q$6:$AA$1115,8) -> 2284 | K6: =VLOOKUP($B6,'[1]Sin Corporativo'!$Q$6:$AA$1115,9) -> 2220 | L6: =VLOOKUP($B6,'[1]Sin Corporativo'!$Q$6:$AA$1115,10) -> 950 | M6: =VLOOKUP($B6,'[1]Sin Corporativo'!$Q$6:$AA$1115,11) -> 869 | N6: =VLOOKUP($B6,'[2]pop-2020-2023'!$I$5:$M$1126,2) -> 20823 | O6: =VLOOKUP($B6,'[2]pop-2020-2023'!$I$5:$M$1126,3) -> 20924 | P6: =VLOOKUP($B6,'[2]pop-2020-2023'!$I$5:$M$1126,4) -> 21109 | Q6: =VLOOKUP($B6,'[2]pop-2020-2023'!$I$5:$M$1126,5) -> 21297 | R6: =VLOOKUP($B6,'[3]Hogares total'!$D$5:$L$1126,6) -> 6942 | S6: =VLOOKUP($B6,'[3]Hogares total'!$D$5:$L$1126,7) -> 7177 | T6: =VLOOKUP($B6,'[3]Hogares total'!$D$5:$L$1126,8) -> 7411 | U6: =VLOOKUP($B6,'[3]Hogares total'!$D$5:$L$1126,9) -> 7650 | W6: =+$E6/O6 -> 0.10710189 | X6: =+$I6/P6 -> 0.11004785 | Y6: =+$M6/Q6 -> 0.040803869 | AA6: =+$E6/S6 -> 0.31224746 | AB6: =+$I6/T6 -> 0.31345298 | AC6: =+$M6/U6 -> 0.11359477 | AD6: =IF(AC6>100%,">100%","")
B7: 05004 | C7: =VLOOKUP(B7,[2]Municipal!$C$15:$D$60549,2) -> Abriaquí | D7: =VLOOKUP($B7,'[1]Sin Corporativo'!$Q$6:$AA$1115,2) -> 127 | E7: =VLOOKUP($B7,'[1]Sin Corporativo'!$Q$6:$AA$1115,3) -> 134 | F7: =VLOOKUP($B7,'[1]Sin Corporativo'!$Q$6:$AA$1115,4) -> 137 | G7: =VLOOKUP($B7,'[1]Sin Corporativo'!$Q$6:$AA$1115,5) -> 136 | H7: =VLOOKUP($B7,'[1]Sin Corporativo'!$Q$6:$AA$1115,6) -> 140 | I7: =VLOOKUP($B7,'[1]Sin Corporativo'!$Q$6:$AA$1115,7) -> 141 | J7: =VLOOKUP($B7,'[1]Sin Corporativo'!$Q$6:$AA$1115,8) -> 131 | K7: =VLOOKUP($B7,'[1]Sin Corporativo'!$Q$6:$AA$1115,9) -> 132 | L7: =VLOOKUP($B7,'[1]Sin Corporativo'!$Q$6:$AA$1115,10) -> 124 | M7: =VLOOKUP($B7,'[1]Sin Corporativo'!$Q$6:$AA$1115,11) -> 122 | N7: =VLOOKUP($B7,'[2]pop-2020-2023'!$I$5:$M$1126,2) -> 2775 | O7: =VLOOKUP($B7,'[2]pop-2020-2023'!$I$5:$M$1126,3) -> 2777 | P7: =VLOOKUP($B7,'[2]pop-2020-2023'!$I$5:$M$1126,4) -> 2804 | Q7: =VLOOKUP($B7,'[2]pop-2020-2023'!$I$5:$M$1126,5) -> 2841 | R7: =VLOOKUP($B7,'[3]Hogares total'!$D$5:$L$1126,6) -> 968 | S7: =VLOOKUP($B7,'[3]Hogares total'!$D$5:$L$1126,7) -> 1004 | T7: =VLOOKUP($B7,'[3]Hogares total'!$D$5:$L$1126,8) -> 1036 | U7: =VLOOKUP($B7,'[3]Hogares total'!$D$5:$L$1126,9) -> 1071 | W7: =+$E7/O7 -> 0.048253511 | X7: =+$I7/P7 -> 0.050285307 | Y7: =+$M7/Q7 -> 0.042942626 | AA7: =+$E7/S7 -> 0.13346614 | AB7: =+$I7/T7 -> 0.13610039 | AC7: =+$M7/U7 -> 0.11391223 | AD7: =IF(AC7>100%,">100%","")
B8: 05021 | C8: =VLOOKUP(B8,[2]Municipal!$C$15:$D$60549,2) -> Alejandría | D8: =VLOOKUP($B8,'[1]Sin Corporativo'!$Q$6:$AA$1115,2) -> 150 | E8: =VLOOKUP($B8,'[1]Sin Corporativo'!$Q$6:$AA$1115,3) -> 361 | F8: =VLOOKUP($B8,'[1]Sin Corporativo'!$Q$6:$AA$1115,4) -> 399 | G8: =VLOOKUP($B8,'[1]Sin Corporativo'!$Q$6:$AA$1115,5) -> 290 | H8: =VLOOKUP($B8,'[1]Sin Corporativo'!$Q$6:$AA$1115,6) -> 623 | I8: =VLOOKUP($B8,'[1]Sin Corporativo'!$Q$6:$AA$1115,7) -> 399 | J8: =VLOOKUP($B8,'[1]Sin Corporativo'!$Q$6:$AA$1115,8) -> 504 | K8: =VLOOKUP($B8,'[1]Sin Corporativo'!$Q$6:$AA$1115,9) -> 595 | L8: =VLOOKUP($B8,'[1]Sin Corporativo'!$Q$6:$AA$1115,10) -> 549 | M8: =VLOOKUP($B8,'[1]Sin Corporativo'!$Q$6:$AA$1115,11) -> 63 | N8: =VLOOKUP($B8,'[2]pop-2020-2023'!$I$5:$M$1126,2) -> 4790 | O8: =VLOOKUP($B8,'[2]pop-2020-2023'!$I$5:$M$1126,3) -> 4845 | P8: =VLOOKUP($B8,'[2]pop-2020-2023'!$I$5:$M$1126,4) -> 4874 | Q8: =VLOOKUP($B8,'[2]pop-2020-2023'!$I$5:$M$1126,5) -> 4912 | R8: =VLOOKUP($B8,'[3]Hogares total'!$D$5:$L$1126,6) -> 1694 | S8: =VLOOKUP($B8,'[3]Hogares total'!$D$5:$L$1126,7) -> 1750 | T8: =VLOOKUP($B8,'[3]Hogares total'!$D$5:$L$1126,8) -> 1807 | U8: =VLOOKUP($B8,'[3]Hogares total'!$D$5:$L$1126,9) -> 1864 | W8: =+$E8/O8 -> 0.074509804 | X8: =+$I8/P8 -> 0.081862946 | Y8: =+$M8/Q8 -> 0.012825733 | AA8: =+$E8/S8 -> 0.20628571 | AB8: =+$I8/T8 -> 0.22080797 | AC8: =+$M8/U8 -> 0.033798283 | AD8: =IF(AC8>100%,">100%","")
B9: 05030 | C9: =VLOOKUP(B9,[2]Municipal!$C$15:$D$60549,2) -> Amagá | D9: =VLOOKUP($B9,'[1]Sin Corporativo'!$Q$6:$AA$1115,2) -> 3199 | E9: =VLOOKUP($B9,'[1]Sin Corporativo'!$Q$6:$AA$1115,3) -> 3600 | F9: =VLOOKUP($B9,'[1]Sin Corporativo'!$Q$6:$AA$1115,4) -> 3520 | G9: =VLOOKUP($B9,'[1]Sin Corporativo'!$Q$6:$AA$1115,5) -> 3539 | H9: =VLOOKUP($B9,'[1]Sin Corporativo'!$Q$6:$AA$1115,6) -> 3426 | I9: =VLOOKUP($B9,'[1]Sin Corporativo'!$Q$6:$AA$1115,7) -> 3355 | J9: =VLOOKUP($B9,'[1]Sin Corporativo'!$Q$6:$AA$1115,8) -> 3378 | K9: =VLOOKUP($B9,'[1]Sin Corporativo'!$Q$6:$AA$1115,9) -> 3160 | L9: =VLOOKUP($B9,'[1]Sin Corporativo'!$Q$6:$AA$1115,10) -> 3359 | M9: =VLOOKUP($B9,'[1]Sin Corporativo'!$Q$6:$AA$1115,11) -> 2942 | N9: =VLOOKUP($B9,'[2]pop-2020-2023'!$I$5:$M$1126,2) -> 31262 | O9: =VLOOKUP($B9,'[2]pop-2020-2023'!$I$5:$M$1126,3) -> 31548 | P9: =VLOOKUP($B9,'[2]pop-2020-2023'!$I$5:$M$1126,4) -> 31851 | Q9: =VLOOKUP($B9,'[2]pop-2020-2023'!$I$5:$M$1126,5) -> 32142 | R9: =VLOOKUP($B9,'[3]Hogares total'!$D$5:$L$1126,6) -> 10371 | S9: =VLOOKUP($B9,'[3]Hogares total'!$D$5:$L$1126,7) -> 10699 | T9: =VLOOKUP($B9,'[3]Hogares total'!$D$5:$L$1126,8) -> 11033 | U9: =VLOOKUP($B9,'[3]Hogares total'!$D$5:$L$1126,9) -> 11379 | W9: =+$E9/O9 -> 0.11411183 | X9: =+$I9/P9 -> 0.10533421 | Y9: =+$M9/Q9 -> 0.09153133 | AA9: =+$E9/S9 -> 0.33648004 | AB9: =+$I9/T9 -> 0.30408774 | AC9: =+$M9/U9 -> 0.25854645 | AD9: =IF(AC9>100%,">100%","")
B10: 05031 | C10: =VLOOKUP(B10,[2]Municipal!$C$15:$D$60549,2) -> Amalfi | D10: =VLOOKUP($B10,'[1]Sin Corporativo'!$Q$6:$AA$1115,2) -> 1329 | E10: =VLOOKUP($B10,'[1]Sin Corporativo'!$Q$6:$AA$1115,3) -> 1668 | F10: =VLOOKUP($B10,'[1]Sin Corporativo'!$Q$6:$AA$1115,4) -> 1409 | G10: =VLOOKUP($B10,'[1]Sin Corporativo'!$Q$6:$AA$1115,5) -> 1336 | H10: =VLOOKUP($B10,'[1]Sin Corporativo'!$Q$6:$AA$1115,6) -> 1414 | I10: =VLOOKUP($B10,'[1]Sin Corporativo'!$Q$6:$AA$1115,7) -> 1279 | J10: =VLOOKUP($B10,'[1]Sin Corporativo'!$Q$6:$AA$1115,8) -> 1293 | K10: =VLOOKUP($B10,'[1]Sin Corporativo'!$Q$6:$AA$1115,9) -> 1252 | L10: =VLOOKUP($B10,'[1]Sin Corporativo'!$Q$6:$AA$1115,10) -> 1329 | M10: =VLOOKUP($B10,'[1]Sin Corporativo'!$Q$6:$AA$1115,11) -> 900 | N10: =VLOOKUP($B10,'[2]pop-2020-2023'!$I$5:$M$1126,2) -> 26876 | O10: =VLOOKUP($B10,'[2]pop-2020-2023'!$I$5:$M$1126,3) -> 27155 | P10: =VLOOKUP($B10,'[2]pop-2020-2023'!$I$5:$M$1126,4) -> 27398 | Q10: =VLOOKUP($B10,'[2]pop-2020-2023'!$I$5:$M$1126,5) -> 27637 | R10: =VLOOKUP($B10,'[3]Hogares total'!$D$5:$L$1126,6) -> 9115 | S10: =VLOOKUP($B10,'[3]Hogares total'!$D$5:$L$1126,7) -> 9413 | T10: =VLOOKUP($B10,'[3]Hogares total'!$D$5:$L$1126,8) -> 9715 | U10: =VLOOKUP($B10,'[3]Hogares total'!$D$5:$L$1126,9) -> 10026 | W10: =+$E10/O10 -> 0.061425152 | X10: =+$I10/P10 -> 0.04668224 | Y10: =+$M10/Q10 -> 0.03256504 | AA10: =+$E10/S10 -> 0.17720174 | AB10: =+$I10/T10 -> 0.13165208 | AC10: =+$M10/U10 -> 0.089766607 | AD10: =IF(AC10>100%,">100%","")
B11: 05034 | C11: =VLOOKUP(B11,[2]Municipal!$C$15:$D$60549,2) -> Andes | D11: =VLOOKUP($B11,'[1]Sin Corporativo'!$Q$6:$AA$1115,2) -> 3136 | E11: =VLOOKUP($B11,'[1]Sin Corporativo'!$Q$6:$AA$1115,3) -> 3670 | F11: =VLOOKUP($B11,'[1]Sin Corporativo'!$Q$6:$AA$1115,4) -> 3732 | G11: =VLOOKUP($B11,'[1]Sin Corporativo'!$Q$6:$AA$1115,5) -> 3818 | H11: =VLOOKUP($B11,'[1]Sin Corporativo'!$Q$6:$AA$1115,6) -> 3902 | I11: =VLOOKUP($B11,'[1]Sin Corporativo'!$Q$6:$AA$1115,7) -> 3889 | J11: =VLOOKUP($B11,'[1]Sin Corporativo'!$Q$6:$AA$1115,8) -> 4028 | K11: =VLOOKUP($B11,'[1]Sin Corporativo'!$Q$6:$AA$1115,9) -> 4010 | L11: =VLOOKUP($B11,'[1]Sin Corporativo'!$Q$6:$AA$1115,10) -> 3892 | M11: =VLOOKUP($B11,'[1]Sin Corporativo'!$Q$6:$AA$1115,11) -> 3371 | N11: =VLOOKUP($B11,'[2]pop-2020-2023'!$I$5:$M$1126,2) -> 44614 | O11: =VLOOKUP($B11,'[2]pop-2020-2023'!$I$5:$M$1126,3) -> 44983 | P11: =VLOOKUP($B11,'[2]pop-2020-2023'!$I$5:$M$1126,4) -> 45394 | Q11: =VLOOKUP($B11,'[2]pop-2020-2023'!$I$5:$M$1126,5) -> 45796 | R11: =VLOOKUP($B11,'[3]Hogares total'!$D$5:$L$1126,6) -> 14180 | S11: =VLOOKUP($B11,'[3]Hogares total'!$D$5:$L$1126,7) -> 14635 | T11: =VLOOKUP($B11,'[3]Hogares total'!$D$5:$L$1126,8) -> 15095 | U11: =VLOOKUP($B11,'[3]Hogares total'!$D$5:$L$1126,9) -> 15573 | W11: =+$E11/O11 -> 0.081586377 | X11: =+$I11/P11 -> 0.085672115 | Y11: =+$M11/Q11 -> 0.073609049 | AA11: =+$E11/S11 -> 0.25076871 | AB11: =+$I11/T11 -> 0.25763498 | AC11: =+$M11/U11 -> 0.21646439 | AD11: =IF(AC11>100%,">100%","")
B12: 05036 | C12: =VLOOKUP(B12,[2]Municipal!$C$15:$D$60549,2) -> Angelópolis | D12: =VLOOKUP($B12,'[1]Sin Corporativo'!$Q$6:$AA$1115,2) -> 260 | E12: =VLOOKUP($B12,'[1]Sin Corporativo'!$Q$6:$AA$1115,3) -> 405 | F12: =VLOOKUP($B12,'[1]Sin Corporativo'!$Q$6:$AA$1115,4) -> 390 | G12: =VLOOKUP($B12,'[1]Sin Corporativo'!$Q$6:$AA$1115,5) -> 391 | H12: =VLOOKUP($B12,'[1]Sin Corporativo'!$Q$6:$AA$1115,6) -> 483 | I12: =VLOOKUP($B12,'[1]Sin Corporativo'!$Q$6:$AA$1115,7) -> 541 | J12: =VLOOKUP($B12,'[1]Sin Corporativo'!$Q$6:$AA$1115,8) -> 626 | K12: =VLOOKUP($B12,'[1]Sin Corporativo'!$Q$6:$AA$1115,9) -> 533 | L12: =VLOOKUP($B12,'[1]Sin Corporativo'!$Q$6:$AA$1115,10) -> 546 | M12: =VLOOKUP($B12,'[1]Sin Corporativo'!$Q$6:$AA$1115,11) -> 370 | N12: =VLOOKUP($B12,'[2]pop-2020-2023'!$I$5:$M$1126,2) -> 5905 | O12: =VLOOKUP($B12,'[2]pop-2020-2023'!$I$5:$M$1126,3) -> 5963 | P12: =VLOOKUP($B12,'[2]pop-2020-2023'!$I$5:$M$1126,4) -> 6010 | Q12: =VLOOKUP($B12,'[2]pop-2020-2023'!$I$5:$M$1126,5) -> 6082 | R12: =VLOOKUP($B12,'[3]Hogares total'!$D$5:$L$1126,6) -> 2003 | S12: =VLOOKUP($B12,'[3]Hogares total'!$D$5:$L$1126,7) -> 2069 | T12: =VLOOKUP($B12,'[3]Hogares total'!$D$5:$L$1126,8) -> 2136 | U12: =VLOOKUP($B12,'[3]Hogares total'!$D$5:$L$1126,9) -> 2203 | W12: =+$E12/O12 -> 0.067918833 | X12: =+$I12/P12 -> 0.090016639 | Y12: =+$M12/Q12 -> 0.060835252 | AA12: =+$E12/S12 -> 0.19574674 | AB12: =+$I12/T12 -> 0.25327715 | AC12: =+$M12/U12 -> 0.16795279 | AD12: =IF(AC12>100%,">100%","")
B13: 05038 | C13: =VLOOKUP(B13,[2]Municipal!$C$15:$D$60549,2) -> Angostura | D13: =VLOOKUP($B13,'[1]Sin Corporativo'!$Q$6:$AA$1115,2) -> 454 | E13: =VLOOKUP($B13,'[1]Sin Corporativo'!$Q$6:$AA$1115,3) -> 464 | F13: =VLOOKUP($B13,'[1]Sin Corporativo'!$Q$6:$AA$1115,4) -> 475 | G13: =VLOOKUP($B13,'[1]Sin Corporativo'!$Q$6:$AA$1115,5) -> 471 | H13: =VLOOKUP($B13,'[1]Sin Corporativo'!$Q$6:$AA$1115,6) -> 467 | I13: =VLOOKUP($B13,'[1]Sin Corporativo'!$Q$6:$AA$1115,7) -> 486 | J13: =VLOOKUP($B13,'[1]Sin Corporativo'!$Q$6:$AA$1115,8) -> 408 | K13: =VLOOKUP($B13,'[1]Sin Corporativo'!$Q$6:$AA$1115,9) -> 384 | L13: =VLOOKUP($B13,'[1]Sin Corporativo'!$Q$6:$AA$1115,10) -> 343 | M13: =VLOOKUP($B13,'[1]Sin Corporativo'!$Q$6:$AA$1115,11) -> 306 | N13: =VLOOKUP($B13,'[2]pop-2020-2023'!$I$5:$M$1126,2) -> 11742 | O13: =VLOOKUP($B13,'[2]pop-2020-2023'!$I$5:$M$1126,3) -> 11783 | P13: =VLOOKUP($B13,'[2]pop-2020-2023'!$I$5:$M$1126,4) -> 11909 | Q13: =VLOOKUP($B13,'[2]pop-2020-2023'!$I$5:$M$1126,5) -> 12005 | R13: =VLOOKUP($B13,'[3]Hogares total'!$D$5:$L$1126,6) -> 3635 | S13: =VLOOKUP($B13,'[3]Hogares total'!$D$5:$L$1126,7) -> 3762 | T13: =VLOOKUP($B13,'[3]Hogares total'!$D$5:$L$1126,8) -> 3886 | U13: =VLOOKUP($B13,'[3]Hogares total'!$D$5:$L$1126,9) -> 4012 | W13: =+$E13/O13 -> 0.039378766 | X13: =+$I13/P13 -> 0.040809472 | Y13: =+$M13/Q13 -> 0.025489379 | AA13: =+$E13/S13 -> 0.12333865 | AB13: =+$I13/T13 -> 0.12506433 | AC13: =+$M13/U13 -> 0.076271186 | AD13: =IF(AC13>100%,">100%","")
B14: 05040 | C14: =VLOOKUP(B14,[2]Municipal!$C$15:$D$60549,2) -> Anorí | D14: =VLOOKUP($B14,'[1]Sin Corporativo'!$Q$6:$AA$1115,2) -> 1180 | E14: =VLOOKUP($B14,'[1]Sin Corporativo'!$Q$6:$AA$1115,3) -> 1177 | F14: =VLOOKUP($B14,'[1]Sin Corporativo'!$Q$6:$AA$1115,4) -> 1221 | G14: =VLOOKUP($B14,'[1]Sin Corporativo'!$Q$6:$AA$1115,5) -> 1203 | H14: =VLOOKUP($B14,'[1]Sin Corporativo'!$Q$6:$AA$1115,6) -> 1191 | I14: =VLOOKUP($B14,'[1]Sin Corporativo'!$Q$6:$AA$1115,7) -> 1708 | J14: =VLOOKUP($B14,'[1]Sin Corporativo'!$Q$6:$AA$1115,8) -> 1800 | K14: =VLOOKUP($B14,'[1]Sin Corporativo'!$Q$6:$AA$1115,9) -> 1786 | L14: =VLOOKUP($B14,'[1]Sin Corporativo'!$Q$6:$AA$1115,10) -> 1315 | M14: =VLOOKUP($B14,'[1]Sin Corporativo'!$Q$6:$AA$1115,11) -> 1703 | N14: =VLOOKUP($B14,'[2]pop-2020-2023'!$I$5:$M$1126,2) -> 18978 | O14: =VLOOKUP($B14,'[2]pop-2020-2023'!$I$5:$M$1126,3) -> 19192 | P14: =VLOOKUP($B14,'[2]pop-2020-2023'!$I$5:$M$1126,4) -> 19349 | Q14: =VLOOKUP($B14,'[2]pop-2020-2023'!$I$5:$M$1126,5) -> 19527 | R14: =VLOOKUP($B14,'[3]Hogares total'!$D$5:$L$1126,6) -> 6257 | S14: =VLOOKUP($B14,'[3]Hogares total'!$D$5:$L$1126,7) -> 6457 | T14: =VLOOKUP($B14,'[3]Hogares total'!$D$5:$L$1126,8) -> 6658 | U14: =VLOOKUP($B14,'[3]Hogares total'!$D$5:$L$1126,9) -> 6865 | W14: =+$E14/O14 -> 0.061327637 | X14: =+$I14/P14 -> 0.088273296 | Y14: =+$M14/Q14 -> 0.087212577 | AA14: =+$E14/S14 -> 0.18228279 | AB14: =+$I14/T14 -> 0.25653349 | AC14: =+$M14/U14 -> 0.24806992 | AD14: =IF(AC14>100%,">100%","")
